Workbook

Sheet Summary
A2: UG & PG Third Semester Major Evaluation Timetable (July-December 2025) | F2: =#REF! -> #REF!
A3: Programme | B3: Course Code | C3: Course Title | D3: Mode of Exam | E3: Date | F3: Present | G3: Absent

Sheet Seating Plan
A1: MCQ Exam November-December 2025
A2: Seating Plan
A3: Date of Examination | D3: 08.04.2026 | G3: IV Sem
A4: Time | G4: Shift:I (10:00 to 11:00 AM)
A5: 1 | B5: Centre for IOT | C5: Lab M005 | D5: 30 | E5: A1 | G5: B1 | H5: BTME24O1043
E6: A2 | G6: B2
E7: A3 | G7: B3
E8: A4 | G8: B4
E9: A5 | G9: B5
E10: A6 | G10: B6
E11: A7 | G11: B7
E12: A8 | G12: B8
E13: A9 | G13: B9
E14: A10 | G14: B10
E15: A11 | G15: B11
E16: A12 | G16: B12
E17: A13 | G17: B13
B18: Code A: | C18: Code B: | E18: A14 | G18: B14
E19: A15 | G19: B15
A20: 2 | B20: Centre for AI | C20: Lab 104 | D20: 50 | E20: A1 | G20: B1
E21: A2 | G21: B2
E22: A3 | G22: B3
E23: A4 | G23: B4
E24: A5 | G24: B5
E25: A6 | G25: B6
E26: A7 | G26: B7
E27: A8 | G27: B8
E28: A9 | G28: B9
E29: A10 | G29: B10
E30: A11 | G30: B11
E31: A12 | G31: B12
E32: A13 | G32: B13
... E42: A23 | G42: B23
B43: Code A: | C43: Code B: | E43: A24 | G43: B24
E44: A25 | G44: B25
A45: 3 | B45: Centre for AI | C45: Lab 105 | D45: 35 | E45: A1 | G45: B1
E46: A2 | G46: B2
E47: A3 | G47: B3
E48: A4 | G48: B4
E49: A5 | G49: B5
...

Sheet Lab M005
A1: MADHAV INSTITUTE OF TECHNOLOGY & SCIENCE, GWALIOR
A2: (Deemed University)
A3: Major Evaluation (July-December 2025 Session)
A4: III semester
A5: Lab Name: M005 Lab (New Building)
A6: Attendance Sheet
A7: Course Name: | C7: =VLOOKUP(D10,Sheet3!G:H,2,0) -> #N/A | G7: ='Seating Plan'!D3 -> 08.04.2026
G8: ='Seating Plan'!G4 -> Shift:I (10:00 to 11:00 AM)
A9: S.No. | B9: Enrollment No. | C9: Name of student | D9: Course code | E9: Password | F9: Seating | G9: Signature
B10: ='Seating Plan'!F5 -> 0 | C10: =VLOOKUP(B10,Sheet3!B:E,2,0) -> #N/A | D10: =VLOOKUP(B10,Sheet3!B:E,3,0) -> #N/A | E10: =VLOOKUP(B10,Sheet3!B:E,4,0) -> #N/A | F10: A1
B11: ='Seating Plan'!F6 -> 0 | C11: =VLOOKUP(B11,Sheet3!B:E,2,0) -> #N/A | D11: =VLOOKUP(B11,Sheet3!B:E,3,0) -> #N/A | E11: =VLOOKUP(B11,Sheet3!B:E,4,0) -> #N/A | F11: A2
B12: ='Seating Plan'!F7 -> 0 | C12: =VLOOKUP(B12,Sheet3!B:E,2,0) -> #N/A | D12: =VLOOKUP(B12,Sheet3!B:E,3,0) -> #N/A | E12: =VLOOKUP(B12,Sheet3!B:E,4,0) -> #N/A | F12: A3
B13: ='Seating Plan'!F8 -> 0 | C13: =VLOOKUP(B13,Sheet3!B:E,2,0) -> #N/A | D13: =VLOOKUP(B13,Sheet3!B:E,3,0) -> #N/A | E13: =VLOOKUP(B13,Sheet3!B:E,4,0) -> #N/A | F13: A4
B14: ='Seating Plan'!F9 -> 0 | C14: =VLOOKUP(B14,Sheet3!B:E,2,0) -> #N/A | D14: =VLOOKUP(B14,Sheet3!B:E,3,0) -> #N/A | E14: =VLOOKUP(B14,Sheet3!B:E,4,0) -> #N/A | F14: A5
B15: ='Seating Plan'!F10 -> 0 | C15: =VLOOKUP(B15,Sheet3!B:E,2,0) -> #N/A | D15: =VLOOKUP(B15,Sheet3!B:E,3,0) -> #N/A | E15: =VLOOKUP(B15,Sheet3!B:E,4,0) -> #N/A | F15: A6
B16: ='Seating Plan'!F11 -> 0 | C16: =VLOOKUP(B16,Sheet3!B:E,2,0) -> #N/A | D16: =VLOOKUP(B16,Sheet3!B:E,3,0) -> #N/A | E16: =VLOOKUP(B16,Sheet3!B:E,4,0) -> #N/A | F16: A7
B17: ='Seating Plan'!F12 -> 0 | C17: =VLOOKUP(B17,Sheet3!B:E,2,0) -> #N/A | D17: =VLOOKUP(B17,Sheet3!B:E,3,0) -> #N/A | E17: =VLOOKUP(B17,Sheet3!B:E,4,0) -> #N/A | F17: A8
B18: ='Seating Plan'!F13 -> 0 | C18: =VLOOKUP(B18,Sheet3!B:E,2,0) -> #N/A | D18: =VLOOKUP(B18,Sheet3!B:E,3,0) -> #N/A | E18: =VLOOKUP(B18,Sheet3!B:E,4,0) -> #N/A | F18: A9
B19: ='Seating Plan'!F14 -> 0 | C19: =VLOOKUP(B19,Sheet3!B:E,2,0) -> #N/A | D19: =VLOOKUP(B19,Sheet3!B:E,3,0) -> #N/A | E19: =VLOOKUP(B19,Sheet3!B:E,4,0) -> #N/A | F19: A10
B20: ='Seating Plan'!F15 -> 0 | C20: =VLOOKUP(B20,Sheet3!B:E,2,0) -> #N/A | D20: =VLOOKUP(B20,Sheet3!B:E,3,0) -> #N/A | E20: =VLOOKUP(B20,Sheet3!B:E,4,0) -> #N/A | F20: A11
B21: ='Seating Plan'!F16 -> 0 | C21: =VLOOKUP(B21,Sheet3!B:E,2,0) -> #N/A | D21: =VLOOKUP(B21,Sheet3!B:E,3,0) -> #N/A | E21: =VLOOKUP(B21,Sheet3!B:E,4,0) -> #N/A | F21: A12
... B24: ='Seating Plan'!F19 -> 0 | C24: =VLOOKUP(B24,Sheet3!B:E,2,0) -> #N/A | D24: =VLOOKUP(B24,Sheet3!B:E,3,0) -> #N/A | E24: =VLOOKUP(B24,Sheet3!B:E,4,0) -> #N/A | F24: A15
A25: 16
A26: 17
A30: MADHAV INSTITUTE OF TECHNOLOGY & SCIENCE, GWALIOR
A31: (Deemed University)
A32: Major Evaluation (July-December 2025 Session)
A33: III semester
A34: Lab Name: M005 Lab (New Building)
A35: Attendance Sheet
A36: Course Name: | C36: =VLOOKUP(D39,Sheet3!G:H,2,0) -> #N/A | G36: ='Seating Plan'!D3 -> 08.04.2026
G37: ='Seating Plan'!G4 -> Shift:I (10:00 to 11:00 AM)
A38: S.No. | B38: Enrollment No. | C38: Name of student | D38: Course code | E38: Password | F38: Seating | G38: Signature
B39: ='Seating Plan'!H5 -> BTME24O1043 | C39: =VLOOKUP(B39,Sheet3!B:E,2,0) -> #N/A | D39: =VLOOKUP(B39,Sheet3!B:E,3,0) -> #N/A | E39: =VLOOKUP(B39,Sheet3!B:E,4,0) -> #N/A | F39: B1
B40: ='Seating Plan'!H6 -> 0 | C40: =VLOOKUP(B40,Sheet3!B:E,2,0) -> #N/A | D40: =VLOOKUP(B40,Sheet3!B:E,3,0) -> #N/A | E40: =VLOOKUP(B40,Sheet3!B:E,4,0) -> #N/A | F40: B2
B41: ='Seating Plan'!H7 -> 0 | C41: =VLOOKUP(B41,Sheet3!B:E,2,0) -> #N/A | D41: =VLOOKUP(B41,Sheet3!B:E,3,0) -> #N/A | E41: =VLOOKUP(B41,Sheet3!B:E,4,0) -> #N/A | F41: B3
B42: ='Seating Plan'!H8 -> 0 | C42: =VLOOKUP(B42,Sheet3!B:E,2,0) -> #N/A | D42: =VLOOKUP(B42,Sheet3!B:E,3,0) -> #N/A | E42: =VLOOKUP(B42,Sheet3!B:E,4,0) -> #N/A | F42: B4
B43: ='Seating Plan'!H9 -> 0 | C43: =VLOOKUP(B43,Sheet3!B:E,2,0) -> #N/A | D43: =VLOOKUP(B43,Sheet3!B:E,3,0) -> #N/A | E43: =VLOOKUP(B43,Sheet3!B:E,4,0) -> #N/A | F43: B5
B44: ='Seating Plan'!H10 -> 0 | C44: =VLOOKUP(B44,Sheet3!B:E,2,0) -> #N/A | D44: =VLOOKUP(B44,Sheet3!B:E,3,0) -> #N/A | E44: =VLOOKUP(B44,Sheet3!B:E,4,0) -> #N/A | F44: B6
B45: ='Seating Plan'!H11 -> 0 | C45: =VLOOKUP(B45,Sheet3!B:E,2,0) -> #N/A | D45: =VLOOKUP(B45,Sheet3!B:E,3,0) -> #N/A | E45: =VLOOKUP(B45,Sheet3!B:E,4,0) -> #N/A | F45: B7
...

Sheet M104
A1: MADHAV INSTITUTE OF TECHNOLOGY & SCIENCE, GWALIOR
A2: (Deemed University)
A3: Major Evaluation (July-December 2025 Session)
A4: III semester
A5: Lab Name: M104 Lab (New Building)
A6: Attendance Sheet
A7: Course Name: | C7: =VLOOKUP(D10,Sheet3!G:H,2,0) -> #N/A | G7: ='Seating Plan'!D$3 -> 08.04.2026
G8: ='Seating Plan'!G$4 -> Shift:I (10:00 to 11:00 AM)
A9: S.No. | B9: Enrollment No. | C9: Name of student | D9: Course code | E9: Password | F9: Seating | G9: Signature
B10: ='Seating Plan'!F20 -> 0 | C10: =VLOOKUP(B10,Sheet3!B:E,2,0) -> #N/A | D10: =VLOOKUP(B10,Sheet3!B:E,3,0) -> #N/A | E10: =VLOOKUP(B10,Sheet3!B:E,4,0) -> #N/A | F10: A1
B11: ='Seating Plan'!F21 -> 0 | C11: =VLOOKUP(B11,Sheet3!B:E,2,0) -> #N/A | D11: =VLOOKUP(B11,Sheet3!B:E,3,0) -> #N/A | E11: =VLOOKUP(B11,Sheet3!B:E,4,0) -> #N/A | F11: A2
B12: ='Seating Plan'!F22 -> 0 | C12: =VLOOKUP(B12,Sheet3!B:E,2,0) -> #N/A | D12: =VLOOKUP(B12,Sheet3!B:E,3,0) -> #N/A | E12: =VLOOKUP(B12,Sheet3!B:E,4,0) -> #N/A | F12: A3
B13: ='Seating Plan'!F23 -> 0 | C13: =VLOOKUP(B13,Sheet3!B:E,2,0) -> #N/A | D13: =VLOOKUP(B13,Sheet3!B:E,3,0) -> #N/A | E13: =VLOOKUP(B13,Sheet3!B:E,4,0) -> #N/A | F13: A4
B14: ='Seating Plan'!F24 -> 0 | C14: =VLOOKUP(B14,Sheet3!B:E,2,0) -> #N/A | D14: =VLOOKUP(B14,Sheet3!B:E,3,0) -> #N/A | E14: =VLOOKUP(B14,Sheet3!B:E,4,0) -> #N/A | F14: A5
B15: ='Seating Plan'!F25 -> 0 | C15: =VLOOKUP(B15,Sheet3!B:E,2,0) -> #N/A | D15: =VLOOKUP(B15,Sheet3!B:E,3,0) -> #N/A | E15: =VLOOKUP(B15,Sheet3!B:E,4,0) -> #N/A | F15: A6
B16: ='Seating Plan'!F26 -> 0 | C16: =VLOOKUP(B16,Sheet3!B:E,2,0) -> #N/A | D16: =VLOOKUP(B16,Sheet3!B:E,3,0) -> #N/A | E16: =VLOOKUP(B16,Sheet3!B:E,4,0) -> #N/A | F16: A7
B17: ='Seating Plan'!F27 -> 0 | C17: =VLOOKUP(B17,Sheet3!B:E,2,0) -> #N/A | D17: =VLOOKUP(B17,Sheet3!B:E,3,0) -> #N/A | E17: =VLOOKUP(B17,Sheet3!B:E,4,0) -> #N/A | F17: A8
B18: ='Seating Plan'!F28 -> 0 | C18: =VLOOKUP(B18,Sheet3!B:E,2,0) -> #N/A | D18: =VLOOKUP(B18,Sheet3!B:E,3,0) -> #N/A | E18: =VLOOKUP(B18,Sheet3!B:E,4,0) -> #N/A | F18: A9
B19: ='Seating Plan'!F29 -> 0 | C19: =VLOOKUP(B19,Sheet3!B:E,2,0) -> #N/A | D19: =VLOOKUP(B19,Sheet3!B:E,3,0) -> #N/A | E19: =VLOOKUP(B19,Sheet3!B:E,4,0) -> #N/A | F19: A10
B20: ='Seating Plan'!F30 -> 0 | C20: =VLOOKUP(B20,Sheet3!B:E,2,0) -> #N/A | D20: =VLOOKUP(B20,Sheet3!B:E,3,0) -> #N/A | E20: =VLOOKUP(B20,Sheet3!B:E,4,0) -> #N/A | F20: A11
B21: ='Seating Plan'!F31 -> 0 | C21: =VLOOKUP(B21,Sheet3!B:E,2,0) -> #N/A | D21: =VLOOKUP(B21,Sheet3!B:E,3,0) -> #N/A | E21: =VLOOKUP(B21,Sheet3!B:E,4,0) -> #N/A | F21: A12
... B34: ='Seating Plan'!F44 -> 0 | C34: =VLOOKUP(B34,Sheet3!B:E,2,0) -> #N/A | D34: =VLOOKUP(B34,Sheet3!B:E,3,0) -> #N/A | E34: =VLOOKUP(B34,Sheet3!B:E,4,0) -> #N/A | F34: A25
A35: MADHAV INSTITUTE OF TECHNOLOGY & SCIENCE, GWALIOR
A36: (Deemed University)
A37: Major Evaluation (July-December 2025 Session)
A38: III semester
A39: Lab Name: M104 Lab (New Building)
A40: Attendance Sheet
A41: Course Name: | C41: =VLOOKUP(D44,Sheet3!G:H,2,0) -> #N/A | G41: ='Seating Plan'!D$3 -> 08.04.2026
G42: ='Seating Plan'!G$4 -> Shift:I (10:00 to 11:00 AM)
A43: S.No. | B43: Enrollment No. | C43: Name of student | D43: Course code | E43: Password | F43: Seating | G43: Signature
B44: ='Seating Plan'!H20 -> 0 | C44: =VLOOKUP(B44,Sheet3!B:E,2,0) -> #N/A | D44: =VLOOKUP(B44,Sheet3!B:E,3,0) -> #N/A | E44: =VLOOKUP(B44,Sheet3!B:E,4,0) -> #N/A | F44: B1
B45: ='Seating Plan'!H21 -> 0 | C45: =VLOOKUP(B45,Sheet3!B:E,2,0) -> #N/A | D45: =VLOOKUP(B45,Sheet3!B:E,3,0) -> #N/A | E45: =VLOOKUP(B45,Sheet3!B:E,4,0) -> #N/A | F45: B2
B46: ='Seating Plan'!H22 -> 0 | C46: =VLOOKUP(B46,Sheet3!B:E,2,0) -> #N/A | D46: =VLOOKUP(B46,Sheet3!B:E,3,0) -> #N/A | E46: =VLOOKUP(B46,Sheet3!B:E,4,0) -> #N/A | F46: B3
B47: ='Seating Plan'!H23 -> 0 | C47: =VLOOKUP(B47,Sheet3!B:E,2,0) -> #N/A | D47: =VLOOKUP(B47,Sheet3!B:E,3,0) -> #N/A | E47: =VLOOKUP(B47,Sheet3!B:E,4,0) -> #N/A | F47: B4
B48: ='Seating Plan'!H24 -> 0 | C48: =VLOOKUP(B48,Sheet3!B:E,2,0) -> #N/A | D48: =VLOOKUP(B48,Sheet3!B:E,3,0) -> #N/A | E48: =VLOOKUP(B48,Sheet3!B:E,4,0) -> #N/A | F48: B5
B49: ='Seating Plan'!H25 -> 0 | C49: =VLOOKUP(B49,Sheet3!B:E,2,0) -> #N/A | D49: =VLOOKUP(B49,Sheet3!B:E,3,0) -> #N/A | E49: =VLOOKUP(B49,Sheet3!B:E,4,0) -> #N/A | F49: B6
B50: ='Seating Plan'!H26 -> 0 | C50: =VLOOKUP(B50,Sheet3!B:E,2,0) -> #N/A | D50: =VLOOKUP(B50,Sheet3!B:E,3,0) -> #N/A | E50: =VLOOKUP(B50,Sheet3!B:E,4,0) -> #N/A | F50: B7
B51: ='Seating Plan'!H27 -> 0 | C51: =VLOOKUP(B51,Sheet3!B:E,2,0) -> #N/A | D51: =VLOOKUP(B51,Sheet3!B:E,3,0) -> #N/A | E51: =VLOOKUP(B51,Sheet3!B:E,4,0) -> #N/A | F51: B8
B52: ='Seating Plan'!H28 -> 0 | C52: =VLOOKUP(B52,Sheet3!B:E,2,0) -> #N/A | D52: =VLOOKUP(B52,Sheet3!B:E,3,0) -> #N/A | E52: =VLOOKUP(B52,Sheet3!B:E,4,0) -> #N/A | F52: B9
...

Sheet Lab 105
A1: MADHAV INSTITUTE OF TECHNOLOGY & SCIENCE, GWALIOR
A2: (Deemed University)
A3: Major Evaluation (July-December 2025 Session)
A4: III semester
A5: Lab Name: Lab 105
A6: Attendance Sheet
A7: Course Name: | C7: =VLOOKUP(D10,Sheet3!G:H,2,0) -> #REF! | G7: ='Seating Plan'!D$3 -> 08.04.2026
G8: ='Seating Plan'!G$4 -> Shift:I (10:00 to 11:00 AM)
A9: S.No. | B9: Enrollment No. | C9: Name of student | D9: Course code | E9: Password | F9: Seating | G9: Signature
B10: ='Seating Plan'!#REF! -> #REF! | C10: =VLOOKUP(B10,Sheet3!B:E,2,0) -> #REF! | D10: =VLOOKUP(B10,Sheet3!B:E,3,0) -> #REF! | E10: =VLOOKUP(B10,Sheet3!B:E,4,0) -> #REF! | F10: A1
B11: ='Seating Plan'!F46 -> 0 | C11: =VLOOKUP(B11,Sheet3!B:E,2,0) -> #N/A | D11: =VLOOKUP(B11,Sheet3!B:E,3,0) -> #N/A | E11: =VLOOKUP(B11,Sheet3!B:E,4,0) -> #N/A | F11: A2
B12: ='Seating Plan'!F47 -> 0 | C12: =VLOOKUP(B12,Sheet3!B:E,2,0) -> #N/A | D12: =VLOOKUP(B12,Sheet3!B:E,3,0) -> #N/A | E12: =VLOOKUP(B12,Sheet3!B:E,4,0) -> #N/A | F12: A3
B13: ='Seating Plan'!F48 -> 0 | C13: =VLOOKUP(B13,Sheet3!B:E,2,0) -> #N/A | D13: =VLOOKUP(B13,Sheet3!B:E,3,0) -> #N/A | E13: =VLOOKUP(B13,Sheet3!B:E,4,0) -> #N/A | F13: A4
B14: ='Seating Plan'!F49 -> 0 | C14: =VLOOKUP(B14,Sheet3!B:E,2,0) -> #N/A | D14: =VLOOKUP(B14,Sheet3!B:E,3,0) -> #N/A | E14: =VLOOKUP(B14,Sheet3!B:E,4,0) -> #N/A | F14: A5
B15: ='Seating Plan'!F50 -> 0 | C15: =VLOOKUP(B15,Sheet3!B:E,2,0) -> #N/A | D15: =VLOOKUP(B15,Sheet3!B:E,3,0) -> #N/A | E15: =VLOOKUP(B15,Sheet3!B:E,4,0) -> #N/A | F15: A6
B16: ='Seating Plan'!F51 -> 0 | C16: =VLOOKUP(B16,Sheet3!B:E,2,0) -> #N/A | D16: =VLOOKUP(B16,Sheet3!B:E,3,0) -> #N/A | E16: =VLOOKUP(B16,Sheet3!B:E,4,0) -> #N/A | F16: A7
B17: ='Seating Plan'!F52 -> 0 | C17: =VLOOKUP(B17,Sheet3!B:E,2,0) -> #N/A | D17: =VLOOKUP(B17,Sheet3!B:E,3,0) -> #N/A | E17: =VLOOKUP(B17,Sheet3!B:E,4,0) -> #N/A | F17: A8
B18: ='Seating Plan'!F53 -> 0 | C18: =VLOOKUP(B18,Sheet3!B:E,2,0) -> #N/A | D18: =VLOOKUP(B18,Sheet3!B:E,3,0) -> #N/A | E18: =VLOOKUP(B18,Sheet3!B:E,4,0) -> #N/A | F18: A9
B19: ='Seating Plan'!F54 -> 0 | C19: =VLOOKUP(B19,Sheet3!B:E,2,0) -> #N/A | D19: =VLOOKUP(B19,Sheet3!B:E,3,0) -> #N/A | E19: =VLOOKUP(B19,Sheet3!B:E,4,0) -> #N/A | F19: A10
B20: ='Seating Plan'!F55 -> 0 | C20: =VLOOKUP(B20,Sheet3!B:E,2,0) -> #N/A | D20: =VLOOKUP(B20,Sheet3!B:E,3,0) -> #N/A | E20: =VLOOKUP(B20,Sheet3!B:E,4,0) -> #N/A | F20: A11
B21: ='Seating Plan'!F56 -> 0 | C21: =VLOOKUP(B21,Sheet3!B:E,2,0) -> #N/A | D21: =VLOOKUP(B21,Sheet3!B:E,3,0) -> #N/A | E21: =VLOOKUP(B21,Sheet3!B:E,4,0) -> #N/A | F21: A12
B22: ='Seating Plan'!F57 -> 0 | C22: =VLOOKUP(B22,Sheet3!B:E,2,0) -> #N/A | D22: =VLOOKUP(B22,Sheet3!B:E,3,0) -> #N/A | E22: =VLOOKUP(B22,Sheet3!B:E,4,0) -> #N/A | F22: A13
... B27: ='Seating Plan'!F62 -> 0 | C27: =VLOOKUP(B27,Sheet3!B:E,2,0) -> #N/A | D27: =VLOOKUP(B27,Sheet3!B:E,3,0) -> #N/A | E27: =VLOOKUP(B27,Sheet3!B:E,4,0) -> #N/A | F27: A18
A30: MADHAV INSTITUTE OF TECHNOLOGY & SCIENCE, GWALIOR
A31: (Deemed University)
A32: Major Evaluation (July-December 2025 Session)
A33: III semester
A34: Lab Name: Lab 105
A35: Attendance Sheet
A36: Course Name: | C36: =VLOOKUP(D39,Sheet3!G:H,2,0) -> #REF! | G36: ='Seating Plan'!D$3 -> 08.04.2026
G37: ='Seating Plan'!G$4 -> Shift:I (10:00 to 11:00 AM)
A38: S.No. | B38: Enrollment No. | C38: Name of student | D38: Course code | E38: Password | F38: Seating | G38: Signature
B39: ='Seating Plan'!#REF! -> #REF! | C39: =VLOOKUP(B39,Sheet3!B:E,2,0) -> #REF! | D39: =VLOOKUP(B39,Sheet3!B:E,3,0) -> #REF! | E39: =VLOOKUP(B39,Sheet3!B:E,4,0) -> #REF! | F39: B1
B40: ='Seating Plan'!H46 -> 0 | C40: =VLOOKUP(B40,Sheet3!B:E,2,0) -> #N/A | D40: =VLOOKUP(B40,Sheet3!B:E,3,0) -> #N/A | E40: =VLOOKUP(B40,Sheet3!B:E,4,0) -> #N/A | F40: B2
B41: ='Seating Plan'!H47 -> 0 | C41: =VLOOKUP(B41,Sheet3!B:E,2,0) -> #N/A | D41: =VLOOKUP(B41,Sheet3!B:E,3,0) -> #N/A | E41: =VLOOKUP(B41,Sheet3!B:E,4,0) -> #N/A | F41: B3
B42: ='Seating Plan'!H48 -> 0 | C42: =VLOOKUP(B42,Sheet3!B:E,2,0) -> #N/A | D42: =VLOOKUP(B42,Sheet3!B:E,3,0) -> #N/A | E42: =VLOOKUP(B42,Sheet3!B:E,4,0) -> #N/A | F42: B4
B43: ='Seating Plan'!H49 -> 0 | C43: =VLOOKUP(B43,Sheet3!B:E,2,0) -> #N/A | D43: =VLOOKUP(B43,Sheet3!B:E,3,0) -> #N/A | E43: =VLOOKUP(B43,Sheet3!B:E,4,0) -> #N/A | F43: B5
B44: ='Seating Plan'!H50 -> 0 | C44: =VLOOKUP(B44,Sheet3!B:E,2,0) -> #N/A | D44: =VLOOKUP(B44,Sheet3!B:E,3,0) -> #N/A | E44: =VLOOKUP(B44,Sheet3!B:E,4,0) -> #N/A | F44: B6
B45: ='Seating Plan'!H51 -> 0 | C45: =VLOOKUP(B45,Sheet3!B:E,2,0) -> #N/A | D45: =VLOOKUP(B45,Sheet3!B:E,3,0) -> #N/A | E45: =VLOOKUP(B45,Sheet3!B:E,4,0) -> #N/A | F45: B7
B46: ='Seating Plan'!H52 -> 0 | C46: =VLOOKUP(B46,Sheet3!B:E,2,0) -> #N/A | D46: =VLOOKUP(B46,Sheet3!B:E,3,0) -> #N/A | E46: =VLOOKUP(B46,Sheet3!B:E,4,0) -> #N/A | F46: B8
...

Sheet M203
A1: MADHAV INSTITUTE OF TECHNOLOGY & SCIENCE, GWALIOR
A2: (Deemed University)
A3: Major Evaluation (July-December 2025 Session)
A4: III semester
A5: Lab Name: M203
A6: Attendance Sheet
A7: Course Name: | C7: =VLOOKUP(D10,Sheet3!G:H,2,0) -> #N/A | G7: ='Seating Plan'!D$3 -> 08.04.2026
G8: ='Seating Plan'!G$4 -> Shift:I (10:00 to 11:00 AM)
A9: S.No. | B9: Enrollment No. | C9: Name of student | D9: Course code | E9: Password | F9: Seating | G9: Signature
B10: ='Seating Plan'!F63 -> 0 | C10: =VLOOKUP(B10,Sheet3!B:E,2,0) -> #N/A | D10: =VLOOKUP(B10,Sheet3!B:E,3,0) -> #N/A | E10: =VLOOKUP(B10,Sheet3!B:E,4,0) -> #N/A | F10: A1
B11: ='Seating Plan'!F64 -> 0 | C11: =VLOOKUP(B11,Sheet3!B:E,2,0) -> #N/A | D11: =VLOOKUP(B11,Sheet3!B:E,3,0) -> #N/A | E11: =VLOOKUP(B11,Sheet3!B:E,4,0) -> #N/A | F11: A2
B12: ='Seating Plan'!F65 -> 0 | C12: =VLOOKUP(B12,Sheet3!B:E,2,0) -> #N/A | D12: =VLOOKUP(B12,Sheet3!B:E,3,0) -> #N/A | E12: =VLOOKUP(B12,Sheet3!B:E,4,0) -> #N/A | F12: A3
B13: ='Seating Plan'!F66 -> 0 | C13: =VLOOKUP(B13,Sheet3!B:E,2,0) -> #N/A | D13: =VLOOKUP(B13,Sheet3!B:E,3,0) -> #N/A | E13: =VLOOKUP(B13,Sheet3!B:E,4,0) -> #N/A | F13: A4
B14: ='Seating Plan'!F67 -> 0 | C14: =VLOOKUP(B14,Sheet3!B:E,2,0) -> #N/A | D14: =VLOOKUP(B14,Sheet3!B:E,3,0) -> #N/A | E14: =VLOOKUP(B14,Sheet3!B:E,4,0) -> #N/A | F14: A5
B15: ='Seating Plan'!F68 -> 0 | C15: =VLOOKUP(B15,Sheet3!B:E,2,0) -> #N/A | D15: =VLOOKUP(B15,Sheet3!B:E,3,0) -> #N/A | E15: =VLOOKUP(B15,Sheet3!B:E,4,0) -> #N/A | F15: A6
B16: ='Seating Plan'!F69 -> 0 | C16: =VLOOKUP(B16,Sheet3!B:E,2,0) -> #N/A | D16: =VLOOKUP(B16,Sheet3!B:E,3,0) -> #N/A | E16: =VLOOKUP(B16,Sheet3!B:E,4,0) -> #N/A | F16: A7
B17: ='Seating Plan'!F70 -> 0 | C17: =VLOOKUP(B17,Sheet3!B:E,2,0) -> #N/A | D17: =VLOOKUP(B17,Sheet3!B:E,3,0) -> #N/A | E17: =VLOOKUP(B17,Sheet3!B:E,4,0) -> #N/A | F17: A8
B18: ='Seating Plan'!F71 -> 0 | C18: =VLOOKUP(B18,Sheet3!B:E,2,0) -> #N/A | D18: =VLOOKUP(B18,Sheet3!B:E,3,0) -> #N/A | E18: =VLOOKUP(B18,Sheet3!B:E,4,0) -> #N/A | F18: A9
B19: ='Seating Plan'!F72 -> 0 | C19: =VLOOKUP(B19,Sheet3!B:E,2,0) -> #N/A | D19: =VLOOKUP(B19,Sheet3!B:E,3,0) -> #N/A | E19: =VLOOKUP(B19,Sheet3!B:E,4,0) -> #N/A | F19: A10
B20: ='Seating Plan'!F73 -> 0 | C20: =VLOOKUP(B20,Sheet3!B:E,2,0) -> #N/A | D20: =VLOOKUP(B20,Sheet3!B:E,3,0) -> #N/A | E20: =VLOOKUP(B20,Sheet3!B:E,4,0) -> #N/A | F20: A11
B21: ='Seating Plan'!F74 -> 0 | C21: =VLOOKUP(B21,Sheet3!B:E,2,0) -> #N/A | D21: =VLOOKUP(B21,Sheet3!B:E,3,0) -> #N/A | E21: =VLOOKUP(B21,Sheet3!B:E,4,0) -> #N/A | F21: A12
... B29: ='Seating Plan'!F82 -> 0 | C29: =VLOOKUP(B29,Sheet3!B:E,2,0) -> #N/A | D29: =VLOOKUP(B29,Sheet3!B:E,3,0) -> #N/A | E29: =VLOOKUP(B29,Sheet3!B:E,4,0) -> #N/A | F29: A20
A30: S.No. | B30: Enrollment No. | C30: Name of student | D30: Course code | E30: Password | F30: Seating | G30: Signature
B31: ='Seating Plan'!F83 -> 0 | C31: =VLOOKUP(B31,Sheet3!B:E,2,0) -> #N/A | D31: =VLOOKUP(B31,Sheet3!B:E,3,0) -> #N/A | E31: =VLOOKUP(B31,Sheet3!B:E,4,0) -> #N/A | F31: A21
B32: ='Seating Plan'!F84 -> 0 | C32: =VLOOKUP(B32,Sheet3!B:E,2,0) -> #N/A | D32: =VLOOKUP(B32,Sheet3!B:E,3,0) -> #N/A | E32: =VLOOKUP(B32,Sheet3!B:E,4,0) -> #N/A | F32: A22
B33: ='Seating Plan'!F85 -> 0 | C33: =VLOOKUP(B33,Sheet3!B:E,2,0) -> #N/A | D33: =VLOOKUP(B33,Sheet3!B:E,3,0) -> #N/A | E33: =VLOOKUP(B33,Sheet3!B:E,4,0) -> #N/A | F33: A23
B34: ='Seating Plan'!F86 -> 0 | C34: =VLOOKUP(B34,Sheet3!B:E,2,0) -> #N/A | D34: =VLOOKUP(B34,Sheet3!B:E,3,0) -> #N/A | E34: =VLOOKUP(B34,Sheet3!B:E,4,0) -> #N/A | F34: A24
B35: ='Seating Plan'!F87 -> 0 | C35: =VLOOKUP(B35,Sheet3!B:E,2,0) -> #N/A | D35: =VLOOKUP(B35,Sheet3!B:E,3,0) -> #N/A | E35: =VLOOKUP(B35,Sheet3!B:E,4,0) -> #N/A | F35: A25
B36: ='Seating Plan'!F88 -> 0 | C36: =VLOOKUP(B36,Sheet3!B:E,2,0) -> #N/A | D36: =VLOOKUP(B36,Sheet3!B:E,3,0) -> #N/A | E36: =VLOOKUP(B36,Sheet3!B:E,4,0) -> #N/A | F36: A26
B37: ='Seating Plan'!F89 -> 0 | C37: =VLOOKUP(B37,Sheet3!B:E,2,0) -> #N/A | D37: =VLOOKUP(B37,Sheet3!B:E,3,0) -> #N/A | E37: =VLOOKUP(B37,Sheet3!B:E,4,0) -> #N/A | F37: A27
B38: ='Seating Plan'!F90 -> 0 | C38: =VLOOKUP(B38,Sheet3!B:E,2,0) -> #N/A | D38: =VLOOKUP(B38,Sheet3!B:E,3,0) -> #N/A | E38: =VLOOKUP(B38,Sheet3!B:E,4,0) -> #N/A | F38: A28
B39: ='Seating Plan'!F91 -> 0 | C39: =VLOOKUP(B39,Sheet3!B:E,2,0) -> #N/A | D39: =VLOOKUP(B39,Sheet3!B:E,3,0) -> #N/A | E39: =VLOOKUP(B39,Sheet3!B:E,4,0) -> #N/A | F39: A29
B40: ='Seating Plan'!F92 -> 0 | C40: =VLOOKUP(B40,Sheet3!B:E,2,0) -> #N/A | D40: =VLOOKUP(B40,Sheet3!B:E,3,0) -> #N/A | E40: =VLOOKUP(B40,Sheet3!B:E,4,0) -> #N/A | F40: A30
B41: ='Seating Plan'!F93 -> 0 | C41: =VLOOKUP(B41,Sheet3!B:E,2,0) -> #N/A | D41: =VLOOKUP(B41,Sheet3!B:E,3,0) -> #N/A | E41: =VLOOKUP(B41,Sheet3!B:E,4,0) -> #N/A | F41: A31
B42: ='Seating Plan'!F94 -> 0 | C42: =VLOOKUP(B42,Sheet3!B:E,2,0) -> #N/A | D42: =VLOOKUP(B42,Sheet3!B:E,3,0) -> #N/A | E42: =VLOOKUP(B42,Sheet3!B:E,4,0) -> #N/A | F42: A32
... B45: ='Seating Plan'!F97 -> 0 | C45: =VLOOKUP(B45,Sheet3!B:E,2,0) -> #N/A | D45: =VLOOKUP(B45,Sheet3!B:E,3,0) -> #N/A | E45: =VLOOKUP(B45,Sheet3!B:E,4,0) -> #N/A | F45: A35
A49: MADHAV INSTITUTE OF TECHNOLOGY & SCIENCE, GWALIOR
A50: (Deemed University)
A51: Major Evaluation (July-December 2025 Session)
A52: III semester
...

Sheet M205
A1: MADHAV INSTITUTE OF TECHNOLOGY & SCIENCE, GWALIOR
A2: (Deemed University)
A3: Major Evaluation (July-December 2025 Session)
A4: III semester
A5: Lab Name: M205 Lab (New Building)
A6: Attendance Sheet
A7: Course Name: | C7: =VLOOKUP(D10,Sheet3!G:H,2,0) -> #N/A | G7: ='Seating Plan'!D$3 -> 08.04.2026
G8: ='Seating Plan'!G$4 -> Shift:I (10:00 to 11:00 AM)
A9: S.No. | B9: Enrollment No. | C9: Name of student | D9: Course code | E9: Password | F9: Seating | G9: Signature
B10: ='Seating Plan'!F98 -> 0 | C10: =VLOOKUP(B10,Sheet3!B:E,2,0) -> #N/A | D10: =VLOOKUP(B10,Sheet3!B:E,3,0) -> #N/A | E10: =VLOOKUP(B10,Sheet3!B:E,4,0) -> #N/A | F10: A1
B11: ='Seating Plan'!F99 -> 0 | C11: =VLOOKUP(B11,Sheet3!B:E,2,0) -> #N/A | D11: =VLOOKUP(B11,Sheet3!B:E,3,0) -> #N/A | E11: =VLOOKUP(B11,Sheet3!B:E,4,0) -> #N/A | F11: A2
B12: ='Seating Plan'!F100 -> 0 | C12: =VLOOKUP(B12,Sheet3!B:E,2,0) -> #N/A | D12: =VLOOKUP(B12,Sheet3!B:E,3,0) -> #N/A | E12: =VLOOKUP(B12,Sheet3!B:E,4,0) -> #N/A | F12: A3
B13: ='Seating Plan'!F101 -> 0 | C13: =VLOOKUP(B13,Sheet3!B:E,2,0) -> #N/A | D13: =VLOOKUP(B13,Sheet3!B:E,3,0) -> #N/A | E13: =VLOOKUP(B13,Sheet3!B:E,4,0) -> #N/A | F13: A4
B14: ='Seating Plan'!F102 -> 0 | C14: =VLOOKUP(B14,Sheet3!B:E,2,0) -> #N/A | D14: =VLOOKUP(B14,Sheet3!B:E,3,0) -> #N/A | E14: =VLOOKUP(B14,Sheet3!B:E,4,0) -> #N/A | F14: A5
B15: ='Seating Plan'!F103 -> 0 | C15: =VLOOKUP(B15,Sheet3!B:E,2,0) -> #N/A | D15: =VLOOKUP(B15,Sheet3!B:E,3,0) -> #N/A | E15: =VLOOKUP(B15,Sheet3!B:E,4,0) -> #N/A | F15: A6
B16: ='Seating Plan'!F104 -> 0 | C16: =VLOOKUP(B16,Sheet3!B:E,2,0) -> #N/A | D16: =VLOOKUP(B16,Sheet3!B:E,3,0) -> #N/A | E16: =VLOOKUP(B16,Sheet3!B:E,4,0) -> #N/A | F16: A7
B17: ='Seating Plan'!F105 -> 0 | C17: =VLOOKUP(B17,Sheet3!B:E,2,0) -> #N/A | D17: =VLOOKUP(B17,Sheet3!B:E,3,0) -> #N/A | E17: =VLOOKUP(B17,Sheet3!B:E,4,0) -> #N/A | F17: A8
B18: ='Seating Plan'!F106 -> 0 | C18: =VLOOKUP(B18,Sheet3!B:E,2,0) -> #N/A | D18: =VLOOKUP(B18,Sheet3!B:E,3,0) -> #N/A | E18: =VLOOKUP(B18,Sheet3!B:E,4,0) -> #N/A | F18: A9
B19: ='Seating Plan'!F107 -> 0 | C19: =VLOOKUP(B19,Sheet3!B:E,2,0) -> #N/A | D19: =VLOOKUP(B19,Sheet3!B:E,3,0) -> #N/A | E19: =VLOOKUP(B19,Sheet3!B:E,4,0) -> #N/A | F19: A10
B20: ='Seating Plan'!F108 -> 0 | C20: =VLOOKUP(B20,Sheet3!B:E,2,0) -> #N/A | D20: =VLOOKUP(B20,Sheet3!B:E,3,0) -> #N/A | E20: =VLOOKUP(B20,Sheet3!B:E,4,0) -> #N/A | F20: A11
B21: ='Seating Plan'!F109 -> 0 | C21: =VLOOKUP(B21,Sheet3!B:E,2,0) -> #N/A | D21: =VLOOKUP(B21,Sheet3!B:E,3,0) -> #N/A | E21: =VLOOKUP(B21,Sheet3!B:E,4,0) -> #N/A | F21: A12
... B29: ='Seating Plan'!F117 -> 0 | C29: =VLOOKUP(B29,Sheet3!B:E,2,0) -> #N/A | D29: =VLOOKUP(B29,Sheet3!B:E,3,0) -> #N/A | E29: =VLOOKUP(B29,Sheet3!B:E,4,0) -> #N/A | F29: A20
A33: MADHAV INSTITUTE OF TECHNOLOGY & SCIENCE, GWALIOR
A34: (Deemed University)
A35: Major Evaluation (July-December 2025 Session)
A36: III semester
A37: Lab Name: M205 Lab (New Building)
A38: Attendance Sheet
A39: Course Name: | C39: =VLOOKUP(D42,Sheet3!G:H,2,0) -> #N/A | G39: ='Seating Plan'!D$3 -> 08.04.2026
G40: ='Seating Plan'!G$4 -> Shift:I (10:00 to 11:00 AM)
A41: S.No. | B41: Enrollment No. | C41: Name of student | D41: Course code | E41: Password | F41: Seating | G41: Signature
B42: ='Seating Plan'!H98 -> 0 | C42: =VLOOKUP(B42,Sheet3!B:E,2,0) -> #N/A | D42: =VLOOKUP(B42,Sheet3!B:E,3,0) -> #N/A | E42: =VLOOKUP(B42,Sheet3!B:E,4,0) -> #N/A | F42: B1
B43: ='Seating Plan'!H99 -> 0 | C43: =VLOOKUP(B43,Sheet3!B:E,2,0) -> #N/A | D43: =VLOOKUP(B43,Sheet3!B:E,3,0) -> #N/A | E43: =VLOOKUP(B43,Sheet3!B:E,4,0) -> #N/A | F43: B2
B44: ='Seating Plan'!H100 -> 0 | C44: =VLOOKUP(B44,Sheet3!B:E,2,0) -> #N/A | D44: =VLOOKUP(B44,Sheet3!B:E,3,0) -> #N/A | E44: =VLOOKUP(B44,Sheet3!B:E,4,0) -> #N/A | F44: B3
B45: ='Seating Plan'!H101 -> 0 | C45: =VLOOKUP(B45,Sheet3!B:E,2,0) -> #N/A | D45: =VLOOKUP(B45,Sheet3!B:E,3,0) -> #N/A | E45: =VLOOKUP(B45,Sheet3!B:E,4,0) -> #N/A | F45: B4
B46: ='Seating Plan'!H102 -> 0 | C46: =VLOOKUP(B46,Sheet3!B:E,2,0) -> #N/A | D46: =VLOOKUP(B46,Sheet3!B:E,3,0) -> #N/A | E46: =VLOOKUP(B46,Sheet3!B:E,4,0) -> #N/A | F46: B5
B47: ='Seating Plan'!H103 -> 0 | C47: =VLOOKUP(B47,Sheet3!B:E,2,0) -> #N/A | D47: =VLOOKUP(B47,Sheet3!B:E,3,0) -> #N/A | E47: =VLOOKUP(B47,Sheet3!B:E,4,0) -> #N/A | F47: B6
B48: ='Seating Plan'!H104 -> 0 | C48: =VLOOKUP(B48,Sheet3!B:E,2,0) -> #N/A | D48: =VLOOKUP(B48,Sheet3!B:E,3,0) -> #N/A | E48: =VLOOKUP(B48,Sheet3!B:E,4,0) -> #N/A | F48: B7
B49: ='Seating Plan'!H105 -> 0 | C49: =VLOOKUP(B49,Sheet3!B:E,2,0) -> #N/A | D49: =VLOOKUP(B49,Sheet3!B:E,3,0) -> #N/A | E49: =VLOOKUP(B49,Sheet3!B:E,4,0) -> #N/A | F49: B8
B50: ='Seating Plan'!H106 -> 0 | C50: =VLOOKUP(B50,Sheet3!B:E,2,0) -> #N/A | D50: =VLOOKUP(B50,Sheet3!B:E,3,0) -> #N/A | E50: =VLOOKUP(B50,Sheet3!B:E,4,0) -> #N/A | F50: B9
...

Sheet M302
A1: MADHAV INSTITUTE OF TECHNOLOGY & SCIENCE, GWALIOR
A2: (Deemed University)
A3: Major Evaluation (July-December 2025 Session)
A4: III semester
A5: Lab Name: Programming Lab (IT)
A6: Attendance Sheet
A7: Course Name: | C7: =VLOOKUP(D10,Sheet3!G:H,2,0) -> #N/A | G7: ='Seating Plan'!D$3 -> 08.04.2026
G8: ='Seating Plan'!G$4 -> Shift:I (10:00 to 11:00 AM)
A9: S.No. | B9: Enrollment No. | C9: Name of student | D9: Course code | E9: Password | F9: Seating | G9: Signature
B10: ='Seating Plan'!F118 -> 0 | C10: =VLOOKUP(B10,Sheet3!B:E,2,0) -> #N/A | D10: =VLOOKUP(B10,Sheet3!B:E,3,0) -> #N/A | E10: =VLOOKUP(B10,Sheet3!B:E,4,0) -> #N/A | F10: A1
B11: ='Seating Plan'!F119 -> 0 | C11: =VLOOKUP(B11,Sheet3!B:E,2,0) -> #N/A | D11: =VLOOKUP(B11,Sheet3!B:E,3,0) -> #N/A | E11: =VLOOKUP(B11,Sheet3!B:E,4,0) -> #N/A | F11: A2
B12: ='Seating Plan'!F120 -> 0 | C12: =VLOOKUP(B12,Sheet3!B:E,2,0) -> #N/A | D12: =VLOOKUP(B12,Sheet3!B:E,3,0) -> #N/A | E12: =VLOOKUP(B12,Sheet3!B:E,4,0) -> #N/A | F12: A3
B13: ='Seating Plan'!F121 -> 0 | C13: =VLOOKUP(B13,Sheet3!B:E,2,0) -> #N/A | D13: =VLOOKUP(B13,Sheet3!B:E,3,0) -> #N/A | E13: =VLOOKUP(B13,Sheet3!B:E,4,0) -> #N/A | F13: A4
B14: ='Seating Plan'!F122 -> 0 | C14: =VLOOKUP(B14,Sheet3!B:E,2,0) -> #N/A | D14: =VLOOKUP(B14,Sheet3!B:E,3,0) -> #N/A | E14: =VLOOKUP(B14,Sheet3!B:E,4,0) -> #N/A | F14: A5
B15: ='Seating Plan'!F123 -> 0 | C15: =VLOOKUP(B15,Sheet3!B:E,2,0) -> #N/A | D15: =VLOOKUP(B15,Sheet3!B:E,3,0) -> #N/A | E15: =VLOOKUP(B15,Sheet3!B:E,4,0) -> #N/A | F15: A6
B16: ='Seating Plan'!F124 -> 0 | C16: =VLOOKUP(B16,Sheet3!B:E,2,0) -> #N/A | D16: =VLOOKUP(B16,Sheet3!B:E,3,0) -> #N/A | E16: =VLOOKUP(B16,Sheet3!B:E,4,0) -> #N/A | F16: A7
B17: ='Seating Plan'!F125 -> 0 | C17: =VLOOKUP(B17,Sheet3!B:E,2,0) -> #N/A | D17: =VLOOKUP(B17,Sheet3!B:E,3,0) -> #N/A | E17: =VLOOKUP(B17,Sheet3!B:E,4,0) -> #N/A | F17: A8
B18: ='Seating Plan'!F126 -> 0 | C18: =VLOOKUP(B18,Sheet3!B:E,2,0) -> #N/A | D18: =VLOOKUP(B18,Sheet3!B:E,3,0) -> #N/A | E18: =VLOOKUP(B18,Sheet3!B:E,4,0) -> #N/A | F18: A9
B19: ='Seating Plan'!F127 -> 0 | C19: =VLOOKUP(B19,Sheet3!B:E,2,0) -> #N/A | D19: =VLOOKUP(B19,Sheet3!B:E,3,0) -> #N/A | E19: =VLOOKUP(B19,Sheet3!B:E,4,0) -> #N/A | F19: A10
B20: ='Seating Plan'!F128 -> 0 | C20: =VLOOKUP(B20,Sheet3!B:E,2,0) -> #N/A | D20: =VLOOKUP(B20,Sheet3!B:E,3,0) -> #N/A | E20: =VLOOKUP(B20,Sheet3!B:E,4,0) -> #N/A | F20: A11
B21: ='Seating Plan'!F129 -> 0 | C21: =VLOOKUP(B21,Sheet3!B:E,2,0) -> #N/A | D21: =VLOOKUP(B21,Sheet3!B:E,3,0) -> #N/A | E21: =VLOOKUP(B21,Sheet3!B:E,4,0) -> #N/A | F21: A12
... B42: ='Seating Plan'!F150 -> 0 | C42: =VLOOKUP(B42,Sheet3!B:E,2,0) -> #N/A | D42: =VLOOKUP(B42,Sheet3!B:E,3,0) -> #N/A | E42: =VLOOKUP(B42,Sheet3!B:E,4,0) -> #N/A | F42: A33
A45: MADHAV INSTITUTE OF TECHNOLOGY & SCIENCE, GWALIOR
A46: (Deemed University)
A47: Major Evaluation (July-December 2025 Session)
A48: III semester
A49: Lab Name: Programming Lab (IT)
A50: Attendance Sheet
A51: Course Name: | C51: =VLOOKUP(D54,Sheet3!G:H,2,0) -> #N/A | G51: ='Seating Plan'!D$3 -> 08.04.2026
G52: ='Seating Plan'!G$4 -> Shift:I (10:00 to 11:00 AM)
A53: S.No. | B53: Enrollment No. | C53: Name of student | D53: Course code | E53: Password | F53: Seating | G53: Signature
B54: ='Seating Plan'!H118 -> 0 | C54: =VLOOKUP(B54,Sheet3!B:E,2,0) -> #N/A | D54: =VLOOKUP(B54,Sheet3!B:E,3,0) -> #N/A | E54: =VLOOKUP(B54,Sheet3!B:E,4,0) -> #N/A | F54: B1
B55: ='Seating Plan'!H119 -> 0 | C55: =VLOOKUP(B55,Sheet3!B:E,2,0) -> #N/A | D55: =VLOOKUP(B55,Sheet3!B:E,3,0) -> #N/A | E55: =VLOOKUP(B55,Sheet3!B:E,4,0) -> #N/A | F55: B2
B56: ='Seating Plan'!H120 -> 0 | C56: =VLOOKUP(B56,Sheet3!B:E,2,0) -> #N/A | D56: =VLOOKUP(B56,Sheet3!B:E,3,0) -> #N/A | E56: =VLOOKUP(B56,Sheet3!B:E,4,0) -> #N/A | F56: B3
B57: ='Seating Plan'!H121 -> 0 | C57: =VLOOKUP(B57,Sheet3!B:E,2,0) -> #N/A | D57: =VLOOKUP(B57,Sheet3!B:E,3,0) -> #N/A | E57: =VLOOKUP(B57,Sheet3!B:E,4,0) -> #N/A | F57: B4
B58: ='Seating Plan'!H122 -> 0 | C58: =VLOOKUP(B58,Sheet3!B:E,2,0) -> #N/A | D58: =VLOOKUP(B58,Sheet3!B:E,3,0) -> #N/A | E58: =VLOOKUP(B58,Sheet3!B:E,4,0) -> #N/A | F58: B5
B59: ='Seating Plan'!H123 -> 0 | C59: =VLOOKUP(B59,Sheet3!B:E,2,0) -> #N/A | D59: =VLOOKUP(B59,Sheet3!B:E,3,0) -> #N/A | E59: =VLOOKUP(B59,Sheet3!B:E,4,0) -> #N/A | F59: B6
B60: ='Seating Plan'!H124 -> 0 | C60: =VLOOKUP(B60,Sheet3!B:E,2,0) -> #N/A | D60: =VLOOKUP(B60,Sheet3!B:E,3,0) -> #N/A | E60: =VLOOKUP(B60,Sheet3!B:E,4,0) -> #N/A | F60: B7
B61: ='Seating Plan'!H125 -> 0 | C61: =VLOOKUP(B61,Sheet3!B:E,2,0) -> #N/A | D61: =VLOOKUP(B61,Sheet3!B:E,3,0) -> #N/A | E61: =VLOOKUP(B61,Sheet3!B:E,4,0) -> #N/A | F61: B8
B62: ='Seating Plan'!H126 -> 0 | C62: =VLOOKUP(B62,Sheet3!B:E,2,0) -> #N/A | D62: =VLOOKUP(B62,Sheet3!B:E,3,0) -> #N/A | E62: =VLOOKUP(B62,Sheet3!B:E,4,0) -> #N/A | F62: B9
...

Sheet HPC lab
A1: MADHAV INSTITUTE OF TECHNOLOGY & SCIENCE, GWALIOR
A2: (Deemed University)
A3: Major Evaluation (July-December 2025 Session)
A4: III semester
A5: Lab Name: HPC Lab
A6: Attendance Sheet
A7: Course Name: | C7: =VLOOKUP(D10,Sheet3!G:H,2,0) -> #N/A | G7: ='Seating Plan'!D$3 -> 08.04.2026
G8: ='Seating Plan'!G$4 -> Shift:I (10:00 to 11:00 AM)
A9: S.No. | B9: Enrollment No. | C9: Name of student | D9: Course code | E9: Password | F9: Seating | G9: Signature
B10: ='Seating Plan'!F151 -> 0 | C10: =VLOOKUP(B10,Sheet3!B:E,2,0) -> #N/A | D10: =VLOOKUP(B10,Sheet3!B:E,3,0) -> #N/A | E10: =VLOOKUP(B10,Sheet3!B:E,4,0) -> #N/A | F10: A1
B11: ='Seating Plan'!F152 -> 0 | C11: =VLOOKUP(B11,Sheet3!B:E,2,0) -> #N/A | D11: =VLOOKUP(B11,Sheet3!B:E,3,0) -> #N/A | E11: =VLOOKUP(B11,Sheet3!B:E,4,0) -> #N/A | F11: A2
B12: ='Seating Plan'!F153 -> 0 | C12: =VLOOKUP(B12,Sheet3!B:E,2,0) -> #N/A | D12: =VLOOKUP(B12,Sheet3!B:E,3,0) -> #N/A | E12: =VLOOKUP(B12,Sheet3!B:E,4,0) -> #N/A | F12: A3
B13: ='Seating Plan'!F154 -> 0 | C13: =VLOOKUP(B13,Sheet3!B:E,2,0) -> #N/A | D13: =VLOOKUP(B13,Sheet3!B:E,3,0) -> #N/A | E13: =VLOOKUP(B13,Sheet3!B:E,4,0) -> #N/A | F13: A4
B14: ='Seating Plan'!F155 -> 0 | C14: =VLOOKUP(B14,Sheet3!B:E,2,0) -> #N/A | D14: =VLOOKUP(B14,Sheet3!B:E,3,0) -> #N/A | E14: =VLOOKUP(B14,Sheet3!B:E,4,0) -> #N/A | F14: A5
B15: ='Seating Plan'!F156 -> 0 | C15: =VLOOKUP(B15,Sheet3!B:E,2,0) -> #N/A | D15: =VLOOKUP(B15,Sheet3!B:E,3,0) -> #N/A | E15: =VLOOKUP(B15,Sheet3!B:E,4,0) -> #N/A | F15: A6
B16: ='Seating Plan'!F157 -> 0 | C16: =VLOOKUP(B16,Sheet3!B:E,2,0) -> #N/A | D16: =VLOOKUP(B16,Sheet3!B:E,3,0) -> #N/A | E16: =VLOOKUP(B16,Sheet3!B:E,4,0) -> #N/A | F16: A7
B17: ='Seating Plan'!F158 -> 0 | C17: =VLOOKUP(B17,Sheet3!B:E,2,0) -> #N/A | D17: =VLOOKUP(B17,Sheet3!B:E,3,0) -> #N/A | E17: =VLOOKUP(B17,Sheet3!B:E,4,0) -> #N/A | F17: A8
B18: ='Seating Plan'!F159 -> 0 | C18: =VLOOKUP(B18,Sheet3!B:E,2,0) -> #N/A | D18: =VLOOKUP(B18,Sheet3!B:E,3,0) -> #N/A | E18: =VLOOKUP(B18,Sheet3!B:E,4,0) -> #N/A | F18: A9
B19: ='Seating Plan'!F160 -> 0 | C19: =VLOOKUP(B19,Sheet3!B:E,2,0) -> #N/A | D19: =VLOOKUP(B19,Sheet3!B:E,3,0) -> #N/A | E19: =VLOOKUP(B19,Sheet3!B:E,4,0) -> #N/A | F19: A10
A20: 11
A21: 12
A22: 13
A26: MADHAV INSTITUTE OF TECHNOLOGY & SCIENCE, GWALIOR
A27: (Deemed University)
A28: Major Evaluation (July-December 2025 Session)
A29: III semester
A30: Lab Name: HPC Lab
A31: Attendance Sheet
A32: Course Name: | C32: =VLOOKUP(D35,Sheet3!G:H,2,0) -> #N/A | G32: ='Seating Plan'!D$3 -> 08.04.2026
G33: ='Seating Plan'!G$4 -> Shift:I (10:00 to 11:00 AM)
A34: S.No. | B34: Enrollment No. | C34: Name of student | D34: Course code | E34: Password | F34: Seating | G34: Signature
B35: ='Seating Plan'!H151 -> 0 | C35: =VLOOKUP(B35,Sheet3!B:E,2,0) -> #N/A | D35: =VLOOKUP(B35,Sheet3!B:E,3,0) -> #N/A | E35: =VLOOKUP(B35,Sheet3!B:E,4,0) -> #N/A | F35: B1
B36: ='Seating Plan'!H152 -> 0 | C36: =VLOOKUP(B36,Sheet3!B:E,2,0) -> #N/A | D36: =VLOOKUP(B36,Sheet3!B:E,3,0) -> #N/A | E36: =VLOOKUP(B36,Sheet3!B:E,4,0) -> #N/A | F36: B2
B37: ='Seating Plan'!H153 -> 0 | C37: =VLOOKUP(B37,Sheet3!B:E,2,0) -> #N/A | D37: =VLOOKUP(B37,Sheet3!B:E,3,0) -> #N/A | E37: =VLOOKUP(B37,Sheet3!B:E,4,0) -> #N/A | F37: B3
B38: ='Seating Plan'!H154 -> 0 | C38: =VLOOKUP(B38,Sheet3!B:E,2,0) -> #N/A | D38: =VLOOKUP(B38,Sheet3!B:E,3,0) -> #N/A | E38: =VLOOKUP(B38,Sheet3!B:E,4,0) -> #N/A | F38: B4
B39: ='Seating Plan'!H155 -> 0 | C39: =VLOOKUP(B39,Sheet3!B:E,2,0) -> #N/A | D39: =VLOOKUP(B39,Sheet3!B:E,3,0) -> #N/A | E39: =VLOOKUP(B39,Sheet3!B:E,4,0) -> #N/A | F39: B5
B40: ='Seating Plan'!H156 -> 0 | C40: =VLOOKUP(B40,Sheet3!B:E,2,0) -> #N/A | D40: =VLOOKUP(B40,Sheet3!B:E,3,0) -> #N/A | E40: =VLOOKUP(B40,Sheet3!B:E,4,0) -> #N/A | F40: B6
B41: ='Seating Plan'!H157 -> 0 | C41: =VLOOKUP(B41,Sheet3!B:E,2,0) -> #N/A | D41: =VLOOKUP(B41,Sheet3!B:E,3,0) -> #N/A | E41: =VLOOKUP(B41,Sheet3!B:E,4,0) -> #N/A | F41: B7
B42: ='Seating Plan'!H158 -> 0 | C42: =VLOOKUP(B42,Sheet3!B:E,2,0) -> #N/A | D42: =VLOOKUP(B42,Sheet3!B:E,3,0) -> #N/A | E42: =VLOOKUP(B42,Sheet3!B:E,4,0) -> #N/A | F42: B8
B43: ='Seating Plan'!H159 -> 0 | C43: =VLOOKUP(B43,Sheet3!B:E,2,0) -> #N/A | D43: =VLOOKUP(B43,Sheet3!B:E,3,0) -> #N/A | E43: =VLOOKUP(B43,Sheet3!B:E,4,0) -> #N/A | F43: B9
...

Sheet Code lab
A1: MADHAV INSTITUTE OF TECHNOLOGY & SCIENCE, GWALIOR
A2: (Deemed University)
A3: Major Evaluation (July-December 2025 Session)
C4: III semester
A5: Lab Name: Code Lab (New Building Third Floor)
A6: Attendance Sheet
A7: Course Name: | C7: =VLOOKUP(D10,Sheet3!G:H,2,0) -> #N/A | G7: ='Seating Plan'!D$3 -> 08.04.2026
G8: ='Seating Plan'!G$4 -> Shift:I (10:00 to 11:00 AM)
A9: S.No. | B9: Enrollment No. | C9: Name of student | D9: Course code | E9: Password | F9: Seating | G9: Signature
B10: ='Seating Plan'!F161 -> 0 | C10: =VLOOKUP(B10,Sheet3!B:E,2,0) -> #N/A | D10: =VLOOKUP(B10,Sheet3!B:E,3,0) -> #N/A | E10: =VLOOKUP(B10,Sheet3!B:E,4,0) -> #N/A | F10: A1
B11: ='Seating Plan'!F162 -> 0 | C11: =VLOOKUP(B11,Sheet3!B:E,2,0) -> #N/A | D11: =VLOOKUP(B11,Sheet3!B:E,3,0) -> #N/A | E11: =VLOOKUP(B11,Sheet3!B:E,4,0) -> #N/A | F11: A2
B12: ='Seating Plan'!F163 -> 0 | C12: =VLOOKUP(B12,Sheet3!B:E,2,0) -> #N/A | D12: =VLOOKUP(B12,Sheet3!B:E,3,0) -> #N/A | E12: =VLOOKUP(B12,Sheet3!B:E,4,0) -> #N/A | F12: A3
B13: ='Seating Plan'!F164 -> 0 | C13: =VLOOKUP(B13,Sheet3!B:E,2,0) -> #N/A | D13: =VLOOKUP(B13,Sheet3!B:E,3,0) -> #N/A | E13: =VLOOKUP(B13,Sheet3!B:E,4,0) -> #N/A | F13: A4
B14: ='Seating Plan'!F165 -> 0 | C14: =VLOOKUP(B14,Sheet3!B:E,2,0) -> #N/A | D14: =VLOOKUP(B14,Sheet3!B:E,3,0) -> #N/A | E14: =VLOOKUP(B14,Sheet3!B:E,4,0) -> #N/A | F14: A5
B15: ='Seating Plan'!F166 -> 0 | C15: =VLOOKUP(B15,Sheet3!B:E,2,0) -> #N/A | D15: =VLOOKUP(B15,Sheet3!B:E,3,0) -> #N/A | E15: =VLOOKUP(B15,Sheet3!B:E,4,0) -> #N/A | F15: A6
B16: ='Seating Plan'!F167 -> 0 | C16: =VLOOKUP(B16,Sheet3!B:E,2,0) -> #N/A | D16: =VLOOKUP(B16,Sheet3!B:E,3,0) -> #N/A | E16: =VLOOKUP(B16,Sheet3!B:E,4,0) -> #N/A | F16: A7
B17: ='Seating Plan'!F168 -> 0 | C17: =VLOOKUP(B17,Sheet3!B:E,2,0) -> #N/A | D17: =VLOOKUP(B17,Sheet3!B:E,3,0) -> #N/A | E17: =VLOOKUP(B17,Sheet3!B:E,4,0) -> #N/A | F17: A8
B18: ='Seating Plan'!F169 -> 0 | C18: =VLOOKUP(B18,Sheet3!B:E,2,0) -> #N/A | D18: =VLOOKUP(B18,Sheet3!B:E,3,0) -> #N/A | E18: =VLOOKUP(B18,Sheet3!B:E,4,0) -> #N/A | F18: A9
B19: ='Seating Plan'!F170 -> 0 | C19: =VLOOKUP(B19,Sheet3!B:E,2,0) -> #N/A | D19: =VLOOKUP(B19,Sheet3!B:E,3,0) -> #N/A | E19: =VLOOKUP(B19,Sheet3!B:E,4,0) -> #N/A | F19: A10
B20: ='Seating Plan'!F171 -> 0 | C20: =VLOOKUP(B20,Sheet3!B:E,2,0) -> #N/A | D20: =VLOOKUP(B20,Sheet3!B:E,3,0) -> #N/A | E20: =VLOOKUP(B20,Sheet3!B:E,4,0) -> #N/A | F20: A11
B21: ='Seating Plan'!F172 -> 0 | C21: =VLOOKUP(B21,Sheet3!B:E,2,0) -> #N/A | D21: =VLOOKUP(B21,Sheet3!B:E,3,0) -> #N/A | E21: =VLOOKUP(B21,Sheet3!B:E,4,0) -> #N/A | F21: A12
B22: ='Seating Plan'!F173 -> 0 | C22: =VLOOKUP(B22,Sheet3!B:E,2,0) -> #N/A | D22: =VLOOKUP(B22,Sheet3!B:E,3,0) -> #N/A | E22: =VLOOKUP(B22,Sheet3!B:E,4,0) -> #N/A | F22: A13
C23: =VLOOKUP(B23,Sheet3!B:E,2,0) -> #N/A | D23: =VLOOKUP(B23,Sheet3!B:E,3,0) -> #N/A | E23: =VLOOKUP(B23,Sheet3!B:E,4,0) -> #N/A
A26: MADHAV INSTITUTE OF TECHNOLOGY & SCIENCE, GWALIOR
A27: (Deemed University)
A28: Major Evaluation (July-December 2025 Session)
C29: III semester
A30: Lab Name: Code Lab (New Building Third Floor)
A31: Attendance Sheet
A32: Course Name: | C32: =VLOOKUP(D35,Sheet3!G:H,2,0) -> #N/A | G32: ='Seating Plan'!D$3 -> 08.04.2026
G33: ='Seating Plan'!G$4 -> Shift:I (10:00 to 11:00 AM)
A34: S.No. | B34: Enrollment No. | C34: Name of student | D34: Course code | E34: Password | F34: Seating | G34: Signature
B35: ='Seating Plan'!H161 -> 0 | C35: =VLOOKUP(B35,Sheet3!B:E,2,0) -> #N/A | D35: =VLOOKUP(B35,Sheet3!B:E,3,0) -> #N/A | E35: =VLOOKUP(B35,Sheet3!B:E,4,0) -> #N/A | F35: B1
B36: ='Seating Plan'!H162 -> 0 | C36: =VLOOKUP(B36,Sheet3!B:E,2,0) -> #N/A | D36: =VLOOKUP(B36,Sheet3!B:E,3,0) -> #N/A | E36: =VLOOKUP(B36,Sheet3!B:E,4,0) -> #N/A | F36: B2
B37: ='Seating Plan'!H163 -> 0 | C37: =VLOOKUP(B37,Sheet3!B:E,2,0) -> #N/A | D37: =VLOOKUP(B37,Sheet3!B:E,3,0) -> #N/A | E37: =VLOOKUP(B37,Sheet3!B:E,4,0) -> #N/A | F37: B3
B38: ='Seating Plan'!H164 -> 0 | C38: =VLOOKUP(B38,Sheet3!B:E,2,0) -> #N/A | D38: =VLOOKUP(B38,Sheet3!B:E,3,0) -> #N/A | E38: =VLOOKUP(B38,Sheet3!B:E,4,0) -> #N/A | F38: B4
B39: ='Seating Plan'!H165 -> 0 | C39: =VLOOKUP(B39,Sheet3!B:E,2,0) -> #N/A | D39: =VLOOKUP(B39,Sheet3!B:E,3,0) -> #N/A | E39: =VLOOKUP(B39,Sheet3!B:E,4,0) -> #N/A | F39: B5
B40: ='Seating Plan'!H166 -> 0 | C40: =VLOOKUP(B40,Sheet3!B:E,2,0) -> #N/A | D40: =VLOOKUP(B40,Sheet3!B:E,3,0) -> #N/A | E40: =VLOOKUP(B40,Sheet3!B:E,4,0) -> #N/A | F40: B6
B41: ='Seating Plan'!H167 -> 0 | C41: =VLOOKUP(B41,Sheet3!B:E,2,0) -> #N/A | D41: =VLOOKUP(B41,Sheet3!B:E,3,0) -> #N/A | E41: =VLOOKUP(B41,Sheet3!B:E,4,0) -> #N/A | F41: B7
B42: ='Seating Plan'!H168 -> 0 | C42: =VLOOKUP(B42,Sheet3!B:E,2,0) -> #N/A | D42: =VLOOKUP(B42,Sheet3!B:E,3,0) -> #N/A | E42: =VLOOKUP(B42,Sheet3!B:E,4,0) -> #N/A | F42: B8
...

Sheet DS-1
A1: MADHAV INSTITUTE OF TECHNOLOGY & SCIENCE, GWALIOR (Deemed University)
A2: Department of Computer Science and Engineering
A3: Continuous Quiz-II (Jan-June 2026)
A4: Lab Name: Data Science Lab-1 (Information Technology)
A5: Attendance Sheet
A6: Program: B.Tech( Computer Science and Engineering) | F6: ='Seating Plan'!D$3 -> 08.04.2026
A7: Semester: IV semester | F7: ='Seating Plan'!G$4 -> Shift:I (10:00 to 11:00 AM)
A8: S.No. | B8: Enrollment No. | C8: Name of student | D8: Course code | E8: Password | F8: Signature
A9: 83 | B9: ='Seating Plan'!F174 -> BTCS24O1086 | C9: =VLOOKUP(B9,Sheet3!B:E,2,0) -> NITIN MALVIYA | D9: =VLOOKUP(B9,Sheet3!B:E,3,0) -> 1524 | E9: =VLOOKUP(B9,Sheet3!B:E,4,0) -> 970962
A10: 84 | B10: ='Seating Plan'!F175 -> BTCS24O1087 | C10: =VLOOKUP(B10,Sheet3!B:E,2,0) -> OM GANDHAWANE | D10: =VLOOKUP(B10,Sheet3!B:E,3,0) -> 1524 | E10: =VLOOKUP(B10,Sheet3!B:E,4,0) -> 616268
A11: 85 | B11: ='Seating Plan'!F176 -> BTCS24O1089 | C11: =VLOOKUP(B11,Sheet3!B:E,2,0) -> PARTH PANCHAL | D11: =VLOOKUP(B11,Sheet3!B:E,3,0) -> 1524 | E11: =VLOOKUP(B11,Sheet3!B:E,4,0) -> 163173
A12: 86 | B12: ='Seating Plan'!F177 -> BTCS24O1090 | C12: =VLOOKUP(B12,Sheet3!B:E,2,0) -> PARV AGRAWAL | D12: =VLOOKUP(B12,Sheet3!B:E,3,0) -> 1524 | E12: =VLOOKUP(B12,Sheet3!B:E,4,0) -> 250326
A13: 87 | B13: ='Seating Plan'!F178 -> BTCS24O1091 | C13: =VLOOKUP(B13,Sheet3!B:E,2,0) -> PIYUSH GAUTAM | D13: =VLOOKUP(B13,Sheet3!B:E,3,0) -> 1524 | E13: =VLOOKUP(B13,Sheet3!B:E,4,0) -> 732430
A14: 88 | B14: ='Seating Plan'!F179 -> BTCS24O1092 | C14: =VLOOKUP(B14,Sheet3!B:E,2,0) -> PIYUSH SHARMA | D14: =VLOOKUP(B14,Sheet3!B:E,3,0) -> 1524 | E14: =VLOOKUP(B14,Sheet3!B:E,4,0) -> 241581
A15: 89 | B15: ='Seating Plan'!F180 -> BTCS24O1093 | C15: =VLOOKUP(B15,Sheet3!B:E,2,0) -> PIYUSH SINGH | D15: =VLOOKUP(B15,Sheet3!B:E,3,0) -> 1524 | E15: =VLOOKUP(B15,Sheet3!B:E,4,0) -> 313682
A16: 90 | B16: ='Seating Plan'!F181 -> BTCS24O1094 | C16: =VLOOKUP(B16,Sheet3!B:E,2,0) -> PRAJVAL SAKI | D16: =VLOOKUP(B16,Sheet3!B:E,3,0) -> 1524 | E16: =VLOOKUP(B16,Sheet3!B:E,4,0) -> 911467
A17: 91 | B17: ='Seating Plan'!F182 -> BTCS24O1095 | C17: =VLOOKUP(B17,Sheet3!B:E,2,0) -> PRAKHAR NEMA | D17: =VLOOKUP(B17,Sheet3!B:E,3,0) -> 1524 | E17: =VLOOKUP(B17,Sheet3!B:E,4,0) -> 768320
A18: 92 | B18: ='Seating Plan'!F183 -> BTCS24O1096 | C18: =VLOOKUP(B18,Sheet3!B:E,2,0) -> PRANJAL BANSAL | D18: =VLOOKUP(B18,Sheet3!B:E,3,0) -> 1524 | E18: =VLOOKUP(B18,Sheet3!B:E,4,0) -> 220382
A19: 93 | B19: ='Seating Plan'!F184 -> BTCS24O1097 | C19: =VLOOKUP(B19,Sheet3!B:E,2,0) -> PRIYANKA CHANDERIYA | D19: =VLOOKUP(B19,Sheet3!B:E,3,0) -> 1524 | E19: =VLOOKUP(B19,Sheet3!B:E,4,0) -> 463541
A20: 94 | B20: ='Seating Plan'!F185 -> BTCS24O1098 | C20: =VLOOKUP(B20,Sheet3!B:E,2,0) -> PRIYANSHI MAHESHWARI | D20: =VLOOKUP(B20,Sheet3!B:E,3,0) -> 1524 | E20: =VLOOKUP(B20,Sheet3!B:E,4,0) -> 447696
... A22: 96 | B22: ='Seating Plan'!F187 -> BTCS24O1101 | C22: =VLOOKUP(B22,Sheet3!B:E,2,0) -> PUSHPENDRA SURYAWANSHI | D22: =VLOOKUP(B22,Sheet3!B:E,3,0) -> 1524 | E22: =VLOOKUP(B22,Sheet3!B:E,4,0) -> 707878
A23: 97 | B23: ='Seating Plan'!H174 -> BTCS24O1102 | C23: =VLOOKUP(B23,Sheet3!B:E,2,0) -> RAHUL BAGHEL | D23: =VLOOKUP(B23,Sheet3!B:E,3,0) -> 1524 | E23: =VLOOKUP(B23,Sheet3!B:E,4,0) -> 278605
A24: 98 | B24: ='Seating Plan'!H175 -> BTCS24O1103 | C24: =VLOOKUP(B24,Sheet3!B:E,2,0) -> RAHUL YADAV | D24: =VLOOKUP(B24,Sheet3!B:E,3,0) -> 1524 | E24: =VLOOKUP(B24,Sheet3!B:E,4,0) -> 805698
A25: 99 | B25: ='Seating Plan'!H176 -> BTCS24O1104 | C25: =VLOOKUP(B25,Sheet3!B:E,2,0) -> RAJEEV RAGHUWANSHI | D25: =VLOOKUP(B25,Sheet3!B:E,3,0) -> 1524 | E25: =VLOOKUP(B25,Sheet3!B:E,4,0) -> 104718
A26: 100 | B26: ='Seating Plan'!H177 -> BTCS24O1105 | C26: =VLOOKUP(B26,Sheet3!B:E,2,0) -> RAJSHI SURYAWANSHI | D26: =VLOOKUP(B26,Sheet3!B:E,3,0) -> 1524 | E26: =VLOOKUP(B26,Sheet3!B:E,4,0) -> 146879
A27: 101 | B27: ='Seating Plan'!H178 -> BTCS24O1106 | C27: =VLOOKUP(B27,Sheet3!B:E,2,0) -> RASAL SINGH NARWARIA | D27: =VLOOKUP(B27,Sheet3!B:E,3,0) -> 1524 | E27: =VLOOKUP(B27,Sheet3!B:E,4,0) -> 461509
A28: 102 | B28: ='Seating Plan'!H179 -> BTCS24O1107 | C28: =VLOOKUP(B28,Sheet3!B:E,2,0) -> RASHI RAJORIYA | D28: =VLOOKUP(B28,Sheet3!B:E,3,0) -> 1524 | E28: =VLOOKUP(B28,Sheet3!B:E,4,0) -> 422350
A29: 103 | B29: ='Seating Plan'!H180 -> BTCS24O1108 | C29: =VLOOKUP(B29,Sheet3!B:E,2,0) -> RIYA BARMAIYA | D29: =VLOOKUP(B29,Sheet3!B:E,3,0) -> 1524 | E29: =VLOOKUP(B29,Sheet3!B:E,4,0) -> 409024
A30: 104 | B30: ='Seating Plan'!H181 -> BTCS24O1109 | C30: =VLOOKUP(B30,Sheet3!B:E,2,0) -> ROHIT ARYA | D30: =VLOOKUP(B30,Sheet3!B:E,3,0) -> 1524 | E30: =VLOOKUP(B30,Sheet3!B:E,4,0) -> 991815
A31: 105 | B31: ='Seating Plan'!H182 -> BTCS24O1110 | C31: =VLOOKUP(B31,Sheet3!B:E,2,0) -> ROHIT MOURYA | D31: =VLOOKUP(B31,Sheet3!B:E,3,0) -> 1524 | E31: =VLOOKUP(B31,Sheet3!B:E,4,0) -> 529591
A32: 106 | B32: ='Seating Plan'!H183 -> BTCS24O1111 | C32: =VLOOKUP(B32,Sheet3!B:E,2,0) -> ROSHAN MODI | D32: =VLOOKUP(B32,Sheet3!B:E,3,0) -> 1524 | E32: =VLOOKUP(B32,Sheet3!B:E,4,0) -> 797700
A33: 107 | B33: ='Seating Plan'!H184 -> BTCS24O1112 | C33: =VLOOKUP(B33,Sheet3!B:E,2,0) -> SACHIN KUMAR | D33: =VLOOKUP(B33,Sheet3!B:E,3,0) -> 1524 | E33: =VLOOKUP(B33,Sheet3!B:E,4,0) -> 600088
A34: 108 | B34: ='Seating Plan'!H185 -> BTCS24O1113 | C34: =VLOOKUP(B34,Sheet3!B:E,2,0) -> SACHIN MAKWANA | D34: =VLOOKUP(B34,Sheet3!B:E,3,0) -> 1524 | E34: =VLOOKUP(B34,Sheet3!B:E,4,0) -> 333168
... A36: 110 | B36: ='Seating Plan'!H187 -> BTCS24O1115 | C36: =VLOOKUP(B36,Sheet3!B:E,2,0) -> SAHIL JAIN | D36: =VLOOKUP(B36,Sheet3!B:E,3,0) -> 1524 | E36: =VLOOKUP(B36,Sheet3!B:E,4,0) -> 442993
A38: Total Present:
A39: Total Absent: | D39: 1. Invigilator Name & Signature
D41: 2. Invigilator Name & Signature
A42: Technical Staff Name & Signature

Sheet Project Lab
A1: MADHAV INSTITUTE OF TECHNOLOGY & SCIENCE, GWALIOR (Deemed University)
A2: Department of Computer Science and Engineering
A3: Continuous Quiz-II (Jan-June 2026)
A4: Lab Name: Project Lab
A5: Attendance Sheet
A6: Program: B.Tech (Computer Science and Engineering) | F6: ='Seating Plan'!D$3 -> 08.04.2026
A7: Semester: IV semester | E7: ='Seating Plan'!G$4 -> Shift:I (10:00 to 11:00 AM)
A8: S.No. | B8: Enrollment No. | C8: Name of student | D8: Course code | E8: Password | F8: Signature
A9: 55 | B9: ='Seating Plan'!F190 -> BTCS24O1058 | C9: =VLOOKUP(B9,Sheet3!B:E,2,0) -> HEMANT MATHUR | D9: =VLOOKUP(B9,Sheet3!B:E,3,0) -> 1524 | E9: =VLOOKUP(B9,Sheet3!B:E,4,0) -> 395384
A10: 56 | B10: ='Seating Plan'!F191 -> BTCS24O1059 | C10: =VLOOKUP(B10,Sheet3!B:E,2,0) -> HIMANSHU RATHORE | D10: =VLOOKUP(B10,Sheet3!B:E,3,0) -> 1524 | E10: =VLOOKUP(B10,Sheet3!B:E,4,0) -> 894581
A11: 57 | B11: ='Seating Plan'!F192 -> BTCS24O1060 | C11: =VLOOKUP(B11,Sheet3!B:E,2,0) -> HITESH SANGHI | D11: =VLOOKUP(B11,Sheet3!B:E,3,0) -> 1524 | E11: =VLOOKUP(B11,Sheet3!B:E,4,0) -> 697478
A12: 58 | B12: ='Seating Plan'!F193 -> BTCS24O1061 | C12: =VLOOKUP(B12,Sheet3!B:E,2,0) -> HRITAM SHRIVASTAVA | D12: =VLOOKUP(B12,Sheet3!B:E,3,0) -> 1524 | E12: =VLOOKUP(B12,Sheet3!B:E,4,0) -> 534353
A13: 59 | B13: ='Seating Plan'!F194 -> BTCS24O1062 | C13: =VLOOKUP(B13,Sheet3!B:E,2,0) -> ISHWAR PATEL | D13: =VLOOKUP(B13,Sheet3!B:E,3,0) -> 1524 | E13: =VLOOKUP(B13,Sheet3!B:E,4,0) -> 463971
A14: 60 | B14: ='Seating Plan'!F195 -> BTCS24O1063 | C14: =VLOOKUP(B14,Sheet3!B:E,2,0) -> JATIN PATIDAR | D14: =VLOOKUP(B14,Sheet3!B:E,3,0) -> 1524 | E14: =VLOOKUP(B14,Sheet3!B:E,4,0) -> 313894
A15: 61 | B15: ='Seating Plan'!F196 -> BTCS24O1064 | C15: =VLOOKUP(B15,Sheet3!B:E,2,0) -> JAYESH SONEKAR | D15: =VLOOKUP(B15,Sheet3!B:E,3,0) -> 1524 | E15: =VLOOKUP(B15,Sheet3!B:E,4,0) -> 321384
A16: 62 | B16: ='Seating Plan'!F197 -> BTCS24O1065 | C16: =VLOOKUP(B16,Sheet3!B:E,2,0) -> JAYHIND AHIRWAR | D16: =VLOOKUP(B16,Sheet3!B:E,3,0) -> 1524 | E16: =VLOOKUP(B16,Sheet3!B:E,4,0) -> 432428
A17: 63 | B17: ='Seating Plan'!F198 -> BTCS24O1066 | C17: =VLOOKUP(B17,Sheet3!B:E,2,0) -> JHNAVI BHADKARIYA | D17: =VLOOKUP(B17,Sheet3!B:E,3,0) -> 1524 | E17: =VLOOKUP(B17,Sheet3!B:E,4,0) -> 925388
A18: 64 | B18: ='Seating Plan'!F199 -> BTCS24O1067 | C18: =VLOOKUP(B18,Sheet3!B:E,2,0) -> KANIKA JAIN | D18: =VLOOKUP(B18,Sheet3!B:E,3,0) -> 1524 | E18: =VLOOKUP(B18,Sheet3!B:E,4,0) -> 711701
A19: 65 | B19: ='Seating Plan'!F200 -> BTCS24O1068 | C19: =VLOOKUP(B19,Sheet3!B:E,2,0) -> KARTIK SINGHAL | D19: =VLOOKUP(B19,Sheet3!B:E,3,0) -> 1524 | E19: =VLOOKUP(B19,Sheet3!B:E,4,0) -> 387503
A20: 66 | B20: ='Seating Plan'!F201 -> BTCS24O1069 | C20: =VLOOKUP(B20,Sheet3!B:E,2,0) -> KHUSHAL SINGH | D20: =VLOOKUP(B20,Sheet3!B:E,3,0) -> 1524 | E20: =VLOOKUP(B20,Sheet3!B:E,4,0) -> 285253
... A22: 68 | B22: ='Seating Plan'!F203 -> BTCS24O1071 | C22: =VLOOKUP(B22,Sheet3!B:E,2,0) -> KHUSHI GARG | D22: =VLOOKUP(B22,Sheet3!B:E,3,0) -> 1524 | E22: =VLOOKUP(B22,Sheet3!B:E,4,0) -> 607052
A23: 69 | B23: ='Seating Plan'!H190 -> BTCS24O1072 | C23: =VLOOKUP(B23,Sheet3!B:E,2,0) -> KISHAN CHAUDHARY | D23: =VLOOKUP(B23,Sheet3!B:E,3,0) -> 1524 | E23: =VLOOKUP(B23,Sheet3!B:E,4,0) -> 691645
A24: 70 | B24: ='Seating Plan'!H191 -> BTCS24O1073 | C24: =VLOOKUP(B24,Sheet3!B:E,2,0) -> KSHITIJ KUMAR SONI | D24: =VLOOKUP(B24,Sheet3!B:E,3,0) -> 1524 | E24: =VLOOKUP(B24,Sheet3!B:E,4,0) -> 645576
A25: 71 | B25: ='Seating Plan'!H192 -> BTCS24O1074 | C25: =VLOOKUP(B25,Sheet3!B:E,2,0) -> KUNAL YADUVANSHI | D25: =VLOOKUP(B25,Sheet3!B:E,3,0) -> 1524 | E25: =VLOOKUP(B25,Sheet3!B:E,4,0) -> 799843
A26: 72 | B26: ='Seating Plan'!H193 -> BTCS24O1075 | C26: =VLOOKUP(B26,Sheet3!B:E,2,0) -> KHUSHI GUPTA | D26: =VLOOKUP(B26,Sheet3!B:E,3,0) -> 1524 | E26: =VLOOKUP(B26,Sheet3!B:E,4,0) -> 387105
A27: 73 | B27: ='Seating Plan'!H194 -> BTCS24O1076 | C27: =VLOOKUP(B27,Sheet3!B:E,2,0) -> LAVANYA BAJPAI | D27: =VLOOKUP(B27,Sheet3!B:E,3,0) -> 1524 | E27: =VLOOKUP(B27,Sheet3!B:E,4,0) -> 736216
A28: 74 | B28: ='Seating Plan'!H195 -> BTCS24O1077 | C28: =VLOOKUP(B28,Sheet3!B:E,2,0) -> MAHI GUPTA | D28: =VLOOKUP(B28,Sheet3!B:E,3,0) -> 1524 | E28: =VLOOKUP(B28,Sheet3!B:E,4,0) -> 619289
A29: 75 | B29: ='Seating Plan'!H196 -> BTCS24O1078 | C29: =VLOOKUP(B29,Sheet3!B:E,2,0) -> MITI DUBEY | D29: =VLOOKUP(B29,Sheet3!B:E,3,0) -> 1524 | E29: =VLOOKUP(B29,Sheet3!B:E,4,0) -> 235414
A30: 76 | B30: ='Seating Plan'!H197 -> BTCS24O1079 | C30: =VLOOKUP(B30,Sheet3!B:E,2,0) -> MOHIT RAJPUT | D30: =VLOOKUP(B30,Sheet3!B:E,3,0) -> 1524 | E30: =VLOOKUP(B30,Sheet3!B:E,4,0) -> 307059
A31: 77 | B31: ='Seating Plan'!H198 -> BTCS24O1080 | C31: =VLOOKUP(B31,Sheet3!B:E,2,0) -> MOHIT SHARMA | D31: =VLOOKUP(B31,Sheet3!B:E,3,0) -> 1524 | E31: =VLOOKUP(B31,Sheet3!B:E,4,0) -> 714733
A32: 78 | B32: ='Seating Plan'!H199 -> BTCS24O1081 | C32: =VLOOKUP(B32,Sheet3!B:E,2,0) -> MUSKAN SOLANKI | D32: =VLOOKUP(B32,Sheet3!B:E,3,0) -> 1524 | E32: =VLOOKUP(B32,Sheet3!B:E,4,0) -> 492102
A33: 79 | B33: ='Seating Plan'!H200 -> BTCS24O1082 | C33: =VLOOKUP(B33,Sheet3!B:E,2,0) -> NAKUL RATHOR | D33: =VLOOKUP(B33,Sheet3!B:E,3,0) -> 1524 | E33: =VLOOKUP(B33,Sheet3!B:E,4,0) -> 782423
A34: 80 | B34: ='Seating Plan'!H201 -> BTCS24O1083 | C34: =VLOOKUP(B34,Sheet3!B:E,2,0) -> NEMISH NAGARIA | D34: =VLOOKUP(B34,Sheet3!B:E,3,0) -> 1524 | E34: =VLOOKUP(B34,Sheet3!B:E,4,0) -> 116171
... A36: 82 | B36: ='Seating Plan'!H203 -> BTCS24O1085 | C36: =VLOOKUP(B36,Sheet3!B:E,2,0) -> NIKHIL YADAV | D36: =VLOOKUP(B36,Sheet3!B:E,3,0) -> 1524 | E36: =VLOOKUP(B36,Sheet3!B:E,4,0) -> 972000
A38: Total Present:
A39: Total Absent: | D39: 1. Invigilator Name & Signature
D41: 2. Invigilator Name & Signature
A42: Technical Staff Name & Signature

Sheet CC Lab
A1: MADHAV INSTITUTE OF TECHNOLOGY & SCIENCE, GWALIOR (Deemed University)
A2: Department of Computer Science and Engineering
A3: Continuous Quiz-II (Jan-June 2026)
A4: Lab Name: CC-lab (Second Floor Architecture Building)
A5: Attendance Sheet
A6: Program: B.Tech (Computer Science and Engineering) | F6: ='Seating Plan'!D$3 -> 08.04.2026
A7: Semester: IV semester | E7: ='Seating Plan'!G$4 -> Shift:I (10:00 to 11:00 AM)
A8: S.No. | B8: Enrollment No. | C8: Name of student | D8: Course code | E8: Password | F8: Signature
A9: 35 | B9: ='Seating Plan'!F205 -> BTCS24O1037 | C9: =VLOOKUP(B9,Sheet3!B:E,2,0) -> BHANUPRATAP GURJAR | D9: =VLOOKUP(B9,Sheet3!B:E,3,0) -> 1524 | E9: =VLOOKUP(B9,Sheet3!B:E,4,0) -> 871062
A10: 36 | B10: ='Seating Plan'!F206 -> BTCS24O1038 | C10: =VLOOKUP(B10,Sheet3!B:E,2,0) -> DEVANSH BHARGAV | D10: =VLOOKUP(B10,Sheet3!B:E,3,0) -> 1524 | E10: =VLOOKUP(B10,Sheet3!B:E,4,0) -> 777755
A11: 37 | B11: ='Seating Plan'!F207 -> BTCS24O1039 | C11: =VLOOKUP(B11,Sheet3!B:E,2,0) -> DHANANJAY SINGH TOMAR | D11: =VLOOKUP(B11,Sheet3!B:E,3,0) -> 1524 | E11: =VLOOKUP(B11,Sheet3!B:E,4,0) -> 400665
A12: 38 | B12: ='Seating Plan'!F208 -> BTCS24O1040 | C12: =VLOOKUP(B12,Sheet3!B:E,2,0) -> DHRUV KUMAR PATEL | D12: =VLOOKUP(B12,Sheet3!B:E,3,0) -> 1524 | E12: =VLOOKUP(B12,Sheet3!B:E,4,0) -> 857343
A13: 39 | B13: ='Seating Plan'!F209 -> BTCS24O1042 | C13: =VLOOKUP(B13,Sheet3!B:E,2,0) -> DIPESH KUMAR | D13: =VLOOKUP(B13,Sheet3!B:E,3,0) -> 1524 | E13: =VLOOKUP(B13,Sheet3!B:E,4,0) -> 904048
A14: 40 | B14: ='Seating Plan'!F210 -> BTCS24O1043 | C14: =VLOOKUP(B14,Sheet3!B:E,2,0) -> DIVYANSH GUPTA | D14: =VLOOKUP(B14,Sheet3!B:E,3,0) -> 1524 | E14: =VLOOKUP(B14,Sheet3!B:E,4,0) -> 975640
A15: 41 | B15: ='Seating Plan'!F211 -> BTCS24O1044 | C15: =VLOOKUP(B15,Sheet3!B:E,2,0) -> DIVYANSH SHEKHAR THAKUR | D15: =VLOOKUP(B15,Sheet3!B:E,3,0) -> 1524 | E15: =VLOOKUP(B15,Sheet3!B:E,4,0) -> 997032
A16: 42 | B16: ='Seating Plan'!F212 -> BTCS24O1045 | C16: =VLOOKUP(B16,Sheet3!B:E,2,0) -> DIVYANSHU DAPAKARA | D16: =VLOOKUP(B16,Sheet3!B:E,3,0) -> 1524 | E16: =VLOOKUP(B16,Sheet3!B:E,4,0) -> 871049
A17: 43 | B17: ='Seating Plan'!F213 -> BTCS24O1046 | C17: =VLOOKUP(B17,Sheet3!B:E,2,0) -> DOLLY REWASIYA | D17: =VLOOKUP(B17,Sheet3!B:E,3,0) -> 1524 | E17: =VLOOKUP(B17,Sheet3!B:E,4,0) -> 315099
A18: 44 | B18: ='Seating Plan'!F214 -> BTCS24O1047 | C18: =VLOOKUP(B18,Sheet3!B:E,2,0) -> EKAGRA GANGIL | D18: =VLOOKUP(B18,Sheet3!B:E,3,0) -> 1524 | E18: =VLOOKUP(B18,Sheet3!B:E,4,0) -> 974986
A19: 45 | B19: ='Seating Plan'!H205 -> BTCS24O1048 | C19: =VLOOKUP(B19,Sheet3!B:E,2,0) -> FARAZ KHALID | D19: =VLOOKUP(B19,Sheet3!B:E,3,0) -> 1524 | E19: =VLOOKUP(B19,Sheet3!B:E,4,0) -> 597297
A20: 46 | B20: ='Seating Plan'!H206 -> BTCS24O1049 | C20: =VLOOKUP(B20,Sheet3!B:E,2,0) -> GOURAV CHOUDHARY | D20: =VLOOKUP(B20,Sheet3!B:E,3,0) -> 1524 | E20: =VLOOKUP(B20,Sheet3!B:E,4,0) -> 391386
A21: 47 | B21: ='Seating Plan'!H207 -> BTCS24O1050 | C21: =VLOOKUP(B21,Sheet3!B:E,2,0) -> HARIOM GOURH | D21: =VLOOKUP(B21,Sheet3!B:E,3,0) -> 1524 | E21: =VLOOKUP(B21,Sheet3!B:E,4,0) -> 943473
A22: 48 | B22: ='Seating Plan'!H208 -> BTCS24O1051 | C22: =VLOOKUP(B22,Sheet3!B:E,2,0) -> HARIOM RATHOR | D22: =VLOOKUP(B22,Sheet3!B:E,3,0) -> 1524 | E22: =VLOOKUP(B22,Sheet3!B:E,4,0) -> 997889
A23: 49 | B23: ='Seating Plan'!H209 -> BTCS24O1052 | C23: =VLOOKUP(B23,Sheet3!B:E,2,0) -> HARSH KUMAR DAS | D23: =VLOOKUP(B23,Sheet3!B:E,3,0) -> 1524 | E23: =VLOOKUP(B23,Sheet3!B:E,4,0) -> 206673
A24: 50 | B24: ='Seating Plan'!H210 -> BTCS24O1053 | C24: =VLOOKUP(B24,Sheet3!B:E,2,0) -> HARSH YADAV | D24: =VLOOKUP(B24,Sheet3!B:E,3,0) -> 1524 | E24: =VLOOKUP(B24,Sheet3!B:E,4,0) -> 453785
A25: 51 | B25: ='Seating Plan'!H211 -> BTCS24O1054 | C25: =VLOOKUP(B25,Sheet3!B:E,2,0) -> HARSHIT MALVIYA | D25: =VLOOKUP(B25,Sheet3!B:E,3,0) -> 1524 | E25: =VLOOKUP(B25,Sheet3!B:E,4,0) -> 823763
A26: 52 | B26: ='Seating Plan'!H212 -> BTCS24O1055 | C26: =VLOOKUP(B26,Sheet3!B:E,2,0) -> HARSHIT SINGH | D26: =VLOOKUP(B26,Sheet3!B:E,3,0) -> 1524 | E26: =VLOOKUP(B26,Sheet3!B:E,4,0) -> 610652
A27: 53 | B27: ='Seating Plan'!H213 -> BTCS24O1056 | C27: =VLOOKUP(B27,Sheet3!B:E,2,0) -> HARSHIT TIWARI | D27: =VLOOKUP(B27,Sheet3!B:E,3,0) -> 1524 | E27: =VLOOKUP(B27,Sheet3!B:E,4,0) -> 601333
A28: 54 | B28: ='Seating Plan'!H214 -> BTCS24O1057 | C28: =VLOOKUP(B28,Sheet3!B:E,2,0) -> HARSHITA | D28: =VLOOKUP(B28,Sheet3!B:E,3,0) -> 1524 | E28: =VLOOKUP(B28,Sheet3!B:E,4,0) -> 998321
A29: 2 | B29: ='Seating Plan'!H215 -> 0 | C29: =VLOOKUP(B29,Sheet3!B:E,2,0) -> #N/A | D29: =VLOOKUP(B29,Sheet3!B:E,3,0) -> #N/A | E29: =VLOOKUP(B29,Sheet3!B:E,4,0) -> #N/A
A30: Total Present:
A31: Total Absent: | D31: 1. Invigilator Name & Signature
D33: 2. Invigilator Name & Signature
A34: Technical Staff Name & Signature

Sheet PL-4
A1: MADHAV INSTITUTE OF TECHNOLOGY & SCIENCE, GWALIOR (Deemed University)
A2: Department of Computer Science and Engineering
A3: Continuous Quiz-II (Jan-June 2026)
A4: Lab Name: PL-4 (CSE)
A5: Attendance Sheet
A6: Program: B.Tech (Computer Science and Engineering) | F6: ='Seating Plan'!D$3 -> 08.04.2026
A7: Semester: IV semester | E7: ='Seating Plan'!G$4 -> Shift:I (10:00 to 11:00 AM)
A8: S.No. | B8: Enrollment No. | C8: Name of student | D8: Course code | E8: Password | F8: Signature
A9: 15 | B9: ='Seating Plan'!F291 -> BTCS24O1017 | C9: =VLOOKUP(B9,Sheet3!B:E,2,0) -> ALAKH GUPTA | D9: =VLOOKUP(B9,Sheet3!B:E,3,0) -> 1524 | E9: =VLOOKUP(B9,Sheet3!B:E,4,0) -> 239080
A10: 16 | B10: ='Seating Plan'!F292 -> BTCS24O1018 | C10: =VLOOKUP(B10,Sheet3!B:E,2,0) -> ALOK KUMAR KUSHWAH | D10: =VLOOKUP(B10,Sheet3!B:E,3,0) -> 1524 | E10: =VLOOKUP(B10,Sheet3!B:E,4,0) -> 926861
A11: 17 | B11: ='Seating Plan'!F293 -> BTCS24O1019 | C11: =VLOOKUP(B11,Sheet3!B:E,2,0) -> AMAN | D11: =VLOOKUP(B11,Sheet3!B:E,3,0) -> 1524 | E11: =VLOOKUP(B11,Sheet3!B:E,4,0) -> 975200
A12: 18 | B12: ='Seating Plan'!F294 -> BTCS24O1020 | C12: =VLOOKUP(B12,Sheet3!B:E,2,0) -> AMAN PANDEY | D12: =VLOOKUP(B12,Sheet3!B:E,3,0) -> 1524 | E12: =VLOOKUP(B12,Sheet3!B:E,4,0) -> 738697
A13: 19 | B13: ='Seating Plan'!F295 -> BTCS24O1021 | C13: =VLOOKUP(B13,Sheet3!B:E,2,0) -> AMAN SINGH | D13: =VLOOKUP(B13,Sheet3!B:E,3,0) -> 1524 | E13: =VLOOKUP(B13,Sheet3!B:E,4,0) -> 438068
A14: 20 | B14: ='Seating Plan'!F296 -> BTCS24O1022 | C14: =VLOOKUP(B14,Sheet3!B:E,2,0) -> AMIT MANMODE | D14: =VLOOKUP(B14,Sheet3!B:E,3,0) -> 1524 | E14: =VLOOKUP(B14,Sheet3!B:E,4,0) -> 989743
A15: 21 | B15: ='Seating Plan'!F297 -> BTCS24O1023 | C15: =VLOOKUP(B15,Sheet3!B:E,2,0) -> ANAS KHAN GAURI | D15: =VLOOKUP(B15,Sheet3!B:E,3,0) -> 1524 | E15: =VLOOKUP(B15,Sheet3!B:E,4,0) -> 775763
A16: 22 | B16: ='Seating Plan'!F298 -> BTCS24O1024 | C16: =VLOOKUP(B16,Sheet3!B:E,2,0) -> ANIKET BHARTI | D16: =VLOOKUP(B16,Sheet3!B:E,3,0) -> 1524 | E16: =VLOOKUP(B16,Sheet3!B:E,4,0) -> 497485
A17: 23 | B17: ='Seating Plan'!F299 -> BTCS24O1025 | C17: =VLOOKUP(B17,Sheet3!B:E,2,0) -> ANKIT KARORIYA | D17: =VLOOKUP(B17,Sheet3!B:E,3,0) -> 1524 | E17: =VLOOKUP(B17,Sheet3!B:E,4,0) -> 783768
A18: 24 | B18: ='Seating Plan'!F300 -> BTCS24O1026 | C18: =VLOOKUP(B18,Sheet3!B:E,2,0) -> ANKUSH KANERIYA | D18: =VLOOKUP(B18,Sheet3!B:E,3,0) -> 1524 | E18: =VLOOKUP(B18,Sheet3!B:E,4,0) -> 897428
A19: 25 | B19: ='Seating Plan'!H291 -> BTCS24O1027 | C19: =VLOOKUP(B19,Sheet3!B:E,2,0) -> ANNIKA SUBHASH | D19: =VLOOKUP(B19,Sheet3!B:E,3,0) -> 1524 | E19: =VLOOKUP(B19,Sheet3!B:E,4,0) -> 834165
A20: 26 | B20: ='Seating Plan'!H292 -> BTCS24O1028 | C20: =VLOOKUP(B20,Sheet3!B:E,2,0) -> ANUSHKA SINGHAL | D20: =VLOOKUP(B20,Sheet3!B:E,3,0) -> 1524 | E20: =VLOOKUP(B20,Sheet3!B:E,4,0) -> 808855
A21: 27 | B21: ='Seating Plan'!H293 -> BTCS24O1029 | C21: =VLOOKUP(B21,Sheet3!B:E,2,0) -> ARYAN PARIHAR | D21: =VLOOKUP(B21,Sheet3!B:E,3,0) -> 1524 | E21: =VLOOKUP(B21,Sheet3!B:E,4,0) -> 691356
A22: 28 | B22: ='Seating Plan'!H294 -> BTCS24O1030 | C22: =VLOOKUP(B22,Sheet3!B:E,2,0) -> ASHU | D22: =VLOOKUP(B22,Sheet3!B:E,3,0) -> 1524 | E22: =VLOOKUP(B22,Sheet3!B:E,4,0) -> 618799
A23: 29 | B23: ='Seating Plan'!H295 -> BTCS24O1031 | C23: =VLOOKUP(B23,Sheet3!B:E,2,0) -> ASTHA SAINI | D23: =VLOOKUP(B23,Sheet3!B:E,3,0) -> 1524 | E23: =VLOOKUP(B23,Sheet3!B:E,4,0) -> 445958
A24: 30 | B24: ='Seating Plan'!H296 -> BTCS24O1032 | C24: =VLOOKUP(B24,Sheet3!B:E,2,0) -> ATHARV SHRIVASTAVA | D24: =VLOOKUP(B24,Sheet3!B:E,3,0) -> 1524 | E24: =VLOOKUP(B24,Sheet3!B:E,4,0) -> 563811
A25: 31 | B25: ='Seating Plan'!H297 -> BTCS24O1033 | C25: =VLOOKUP(B25,Sheet3!B:E,2,0) -> AYUSH | D25: =VLOOKUP(B25,Sheet3!B:E,3,0) -> 1524 | E25: =VLOOKUP(B25,Sheet3!B:E,4,0) -> 220309
A26: 32 | B26: ='Seating Plan'!H298 -> BTCS24O1034 | C26: =VLOOKUP(B26,Sheet3!B:E,2,0) -> AYUSH KOUSHAL | D26: =VLOOKUP(B26,Sheet3!B:E,3,0) -> 1524 | E26: =VLOOKUP(B26,Sheet3!B:E,4,0) -> 637872
A27: 33 | B27: ='Seating Plan'!H299 -> BTCS24O1035 | C27: =VLOOKUP(B27,Sheet3!B:E,2,0) -> AYUSH NAGAR | D27: =VLOOKUP(B27,Sheet3!B:E,3,0) -> 1524 | E27: =VLOOKUP(B27,Sheet3!B:E,4,0) -> 317232
A28: 34 | B28: ='Seating Plan'!H300 -> BTCS24O1036 | C28: =VLOOKUP(B28,Sheet3!B:E,2,0) -> BHANU PRATAP SINGH CHAUHAN | D28: =VLOOKUP(B28,Sheet3!B:E,3,0) -> 1524 | E28: =VLOOKUP(B28,Sheet3!B:E,4,0) -> 964350
A29: 99 | B29: ='Seating Plan'!H301 -> 0 | C29: =VLOOKUP(B29,Sheet3!B:E,2,0) -> #N/A | D29: =VLOOKUP(B29,Sheet3!B:E,3,0) -> #N/A | E29: =VLOOKUP(B29,Sheet3!B:E,4,0) -> #N/A
A31: Total Present:
